Workbook

Sheet 📋 Tabela de Alimentos
B2: 📋 TABELA NUTRICIONAL DE ALIMENTOS — Fonte: TACO/UNICAMP · TBCA/USP
B3: Valores por 100g de alimento. Fonte: Tabela TACO 4ª Ed. (NEPA/UNICAMP) e TBCA/USP. Consulte sempre um nutricionista para orientação personalizada.
B5: Legenda de categorias:
B6: Alimento | C6: Categoria | D6: Kcal /100g | E6: Proteínas (g/100g) | F6: Carboidratos (g/100g) | G6: Gorduras (g/100g) | H6: Fibras (g/100g) | I6: Kcal por grama | J6: Observação / Fonte
B7: 🌾 Carboidratos / Cereais e Derivados
B8: Arroz branco cozido | C8: 🌾 Carboidratos / Cereais e Derivados | D8: 128 | E8: 2.5 | F8: 28.1 | G8: 0.2 | H8: 1.6 | I8: =D8/100 -> 1.28 | J8: TACO - porção 100g cozido
B9: Arroz integral cozido | C9: 🌾 Carboidratos / Cereais e Derivados | D9: 124 | E9: 2.6 | F9: 25.8 | G9: 1 | H9: 2.7 | I9: =D9/100 -> 1.24 | J9: TACO - mais fibras que o branco
B10: Macarrão cozido | C10: 🌾 Carboidratos / Cereais e Derivados | D10: 158 | E10: 4.8 | F10: 31.7 | G10: 0.8 | H10: 1.5 | I10: =D10/100 -> 1.58 | J10: TACO - sem molho
B11: Macarrão integral cozido | C11: 🌾 Carboidratos / Cereais e Derivados | D11: 141 | E11: 5.2 | F11: 28.6 | G11: 1.1 | H11: 3.2 | I11: =D11/100 -> 1.41 | J11: TACO - mais fibras
B12: Pão francês | C12: 🌾 Carboidratos / Cereais e Derivados | D12: 300 | E12: 8 | F12: 58.6 | G12: 3.1 | H12: 2.3 | I12: =D12/100 -> 3 | J12: TACO - 50g = 1 unidade
B13: Pão integral | C13: 🌾 Carboidratos / Cereais e Derivados | D13: 253 | E13: 8.8 | F13: 46.7 | G13: 3.5 | H13: 5.7 | I13: =D13/100 -> 2.53 | J13: TACO - fonte de fibras
B14: Aveia em flocos | C14: 🌾 Carboidratos / Cereais e Derivados | D14: 394 | E14: 13.9 | F14: 66.6 | G14: 8.5 | H14: 9.1 | I14: =D14/100 -> 3.94 | J14: TACO - excelente fibra solúvel
B15: Batata inglesa cozida | C15: 🌾 Carboidratos / Cereais e Derivados | D15: 87 | E15: 1.9 | F15: 19.7 | G15: 0.1 | H15: 1.8 | I15: =D15/100 -> 0.87 | J15: TACO - sem pele
B16: Batata doce cozida | C16: 🌾 Carboidratos / Cereais e Derivados | D16: 110 | E16: 1.4 | F16: 26 | G16: 0.1 | H16: 2.7 | I16: =D16/100 -> 1.1 | J16: TACO - índice glicêmico médio
B17: Mandioca cozida | C17: 🌾 Carboidratos / Cereais e Derivados | D17: 149 | E17: 0.9 | F17: 35.3 | G17: 0.3 | H17: 1.9 | I17: =D17/100 -> 1.49 | J17: TACO - aipim/macaxeira
B18: Tapioca (goma) | C18: 🌾 Carboidratos / Cereais e Derivados | D18: 354 | E18: 0.1 | F18: 87.8 | G18: 0.3 | H18: 0.2 | I18: =D18/100 -> 3.54 | J18: TACO - alta em carboidrato
B19: Cuscuz de milho | C19: 🌾 Carboidratos / Cereais e Derivados | D19: 337 | E19: 8.1 | F19: 71.4 | G19: 1.2 | H19: 2.8 | I19: =D19/100 -> 3.37 | J19: TACO - seco
... B21: Granola | C21: 🌾 Carboidratos / Cereais e Derivados | D21: 398 | E21: 8.8 | F21: 66.4 | G21: 9.7 | H21: 5 | I21: =D21/100 -> 3.98 | J21: TACO - verificar açúcar
B23: 🥩 Proteínas Animais — Carnes e Peixes
B24: Frango filé grelhado | C24: 🥩 Proteínas Animais — Carnes e Peixes | D24: 163 | E24: 31.5 | F24: 0 | G24: 3.7 | H24: 0 | I24: =D24/100 -> 1.63 | J24: TACO - peito sem pele
B25: Frango coxa s/ pele grelhada | C25: 🥩 Proteínas Animais — Carnes e Peixes | D25: 215 | E25: 26.8 | F25: 0 | G25: 12 | H25: 0 | I25: =D25/100 -> 2.15 | J25: TACO - coxa sem pele
B26: Carne bovina patinho grelhado | C26: 🥩 Proteínas Animais — Carnes e Peixes | D26: 219 | E26: 35 | F26: 0 | G26: 8.5 | H26: 0 | I26: =D26/100 -> 2.19 | J26: TACO - corte magro
B27: Carne bovina alcatra grelhada | C27: 🥩 Proteínas Animais — Carnes e Peixes | D27: 237 | E27: 32.8 | F27: 0 | G27: 11.4 | H27: 0 | I27: =D27/100 -> 2.37 | J27: TACO
B28: Tilápia grelhada | C28: 🥩 Proteínas Animais — Carnes e Peixes | D28: 128 | E28: 26.2 | F28: 0 | G28: 2.6 | H28: 0 | I28: =D28/100 -> 1.28 | J28: TACO - peixe magro
B29: Salmão assado | C29: 🥩 Proteínas Animais — Carnes e Peixes | D29: 246 | E29: 27.3 | F29: 0 | G29: 15 | H29: 0 | I29: =D29/100 -> 2.46 | J29: TACO - rico em ômega-3
B30: Atum em água (lata) | C30: 🥩 Proteínas Animais — Carnes e Peixes | D30: 119 | E30: 26.3 | F30: 0 | G30: 1.3 | H30: 0 | I30: =D30/100 -> 1.19 | J30: TACO - sem óleo
B31: Sardinha assada | C31: 🥩 Proteínas Animais — Carnes e Peixes | D31: 270 | E31: 30.3 | F31: 0 | G31: 16 | H31: 0 | I31: =D31/100 -> 2.7 | J31: TACO - com osso
B32: Camarão cozido | C32: 🥩 Proteínas Animais — Carnes e Peixes | D32: 115 | E32: 24.4 | F32: 0 | G32: 1.5 | H32: 0 | I32: =D32/100 -> 1.15 | J32: TACO
B33: Ovo inteiro cozido | C33: 🥩 Proteínas Animais — Carnes e Peixes | D33: 146 | E33: 13.3 | F33: 0.6 | G33: 10 | H33: 0 | I33: =D33/100 -> 1.46 | J33: TACO - 1 ovo ≈ 50g
B34: Clara de ovo cozida | C34: 🥩 Proteínas Animais — Carnes e Peixes | D34: 52 | E34: 11.1 | F34: 0.8 | G34: 0.2 | H34: 0 | I34: =D34/100 -> 0.52 | J34: TACO - baixa caloria
B35: Bisteca suína grelhada | C35: 🥩 Proteínas Animais — Carnes e Peixes | D35: 280 | E35: 28.9 | F35: 0 | G35: 17.4 | H35: 0 | I35: =D35/100 -> 2.8 | J35: TACO
B36: Peito de peru fatiado | C36: 🥩 Proteínas Animais — Carnes e Peixes | D36: 109 | E36: 17.4 | F36: 1.9 | G36: 3.6 | H36: 0 | I36: =D36/100 -> 1.09 | J36: TACO — 1 fatia ≈ 15g = ~16 kcal. Baixo teor de gordura
B38: 🫘 Proteínas Vegetais — Leguminosas
B39: Feijão preto cozido | C39: 🫘 Proteínas Vegetais — Leguminosas | D39: 77 | E39: 4.5 | F39: 13.6 | G39: 0.5 | H39: 8.4 | I39: =D38/100 -> 0 | J39: TACO - rico em ferro
B40: Feijão carioca cozido | C40: 🫘 Proteínas Vegetais — Leguminosas | D40: 76 | E40: 4.8 | F40: 13 | G40: 0.5 | H40: 8.5 | I40: =D39/100 -> 0.77 | J40: TACO - mais consumido no BR
B41: Lentilha cozida | C41: 🫘 Proteínas Vegetais — Leguminosas | D41: 93 | E41: 6.3 | F41: 15.7 | G41: 0.5 | H41: 3.7 | I41: =D40/100 -> 0.76 | J41: TACO
B42: Grão-de-bico cozido | C42: 🫘 Proteínas Vegetais — Leguminosas | D42: 164 | E42: 9 | F42: 27.4 | G42: 2.6 | H42: 6 | I42: =D41/100 -> 0.93 | J42: TACO - proteína completa
B43: Ervilha cozida | C43: 🫘 Proteínas Vegetais — Leguminosas | D43: 95 | E43: 6.5 | F43: 16.8 | G43: 0.2 | H43: 6 | I43: =D42/100 -> 1.64 | J43: TACO
B44: Soja cozida | C44: 🫘 Proteínas Vegetais — Leguminosas | D44: 141 | E44: 13.6 | F44: 12.1 | G44: 5.7 | H44: 9 | I44: =D43/100 -> 0.95 | J44: TACO - proteína vegetal completa
B45: Tofu | C45: 🫘 Proteínas Vegetais — Leguminosas | D45: 68 | E45: 6.6 | F45: 1.2 | G45: 4.2 | H45: 0.3 | I45: =D44/100 -> 1.41 | J45: TBCA/USP - proteína vegetal
...

Sheet 🍽️ Plano do Dia
B2: 🍽️ PLANO ALIMENTAR DIÁRIO — CONTROLE DE CALORIAS E MACROS
B3: Digite o nome do alimento na coluna C e a porção (g) na coluna E. Os valores nutricionais são calculados automaticamente via VLOOKUP na tabela de referência.
B4: ⚙️ CONFIGURAÇÕES DO DIA | E4: Meta Calórica (kcal): | F4: 2000 | G4: Peso Corporal (kg): | H4: 70 | I4: Objetivo: | J4: Emagrecimento
B5: 💊 Necessidade Proteica (g/kg × peso): | E5: Fator prot (g/kg): | F5: 1.8 | G5: Meta prot (g): | H5: =H4*F5 -> 126 | I5: Meta carbs (g): | J5: =F4*0.5/4 -> 250
B7: # | C7: Alimento | D7: Refeição | E7: Porção (g) | F7: Calorias (kcal) | G7: Proteínas (g) | H7: Carboidratos (g) | I7: Gorduras (g) | J7: Fibras (g) | K7: % Meta Calórica | L7: Medida Ref.
B8: ☀️ Café da Manhã
B9: 1 | C9: Café sem açúcar | D9: ☀️ Café da Manhã | E9: 200 | F9: =IFERROR(VLOOKUP(C9,'📋 Tabela de Alimentos'!$B$7:$J$300,3,0)*E9/100,0) -> 4 | G9: =IFERROR(VLOOKUP(C9,'📋 Tabela de Alimentos'!$B$7:$J$300,4,0)*E9/100,0) -> 0.6 | H9: =IFERROR(VLOOKUP(C9,'📋 Tabela de Alimentos'!$B$7:$J$300,5,0)*E9/100,0) -> 0 | I9: =IFERROR(VLOOKUP(C9,'📋 Tabela de Alimentos'!$B$7:$J$300,6,0)*E9/100,0) -> 0 | J9: =IFERROR(VLOOKUP(C9,'📋 Tabela de Alimentos'!$B$7:$J$300,7,0)*E9/100,0) -> 0 | K9: =IFERROR(F9/$F$4,0) -> 0.002 | L9: 200ml
B10: 2 | C10: Pão francês | D10: ☀️ Café da Manhã | E10: 50 | F10: =IFERROR(VLOOKUP(C10,'📋 Tabela de Alimentos'!$B$7:$J$300,3,0)*E10/100,0) -> 150 | G10: =IFERROR(VLOOKUP(C10,'📋 Tabela de Alimentos'!$B$7:$J$300,4,0)*E10/100,0) -> 4 | H10: =IFERROR(VLOOKUP(C10,'📋 Tabela de Alimentos'!$B$7:$J$300,5,0)*E10/100,0) -> 29.3 | I10: =IFERROR(VLOOKUP(C10,'📋 Tabela de Alimentos'!$B$7:$J$300,6,0)*E10/100,0) -> 1.55 | J10: =IFERROR(VLOOKUP(C10,'📋 Tabela de Alimentos'!$B$7:$J$300,7,0)*E10/100,0) -> 1.15 | K10: =IFERROR(F10/$F$4,0) -> 0.075 | L10: 50g = 1 unidade
B11: 3 | C11: Requeijão light | D11: ☀️ Café da Manhã | E11: 15 | F11: =IFERROR(VLOOKUP(C11,'📋 Tabela de Alimentos'!$B$7:$J$300,3,0)*E11/100,0) -> 22.8 | G11: =IFERROR(VLOOKUP(C11,'📋 Tabela de Alimentos'!$B$7:$J$300,4,0)*E11/100,0) -> 1.125 | H11: =IFERROR(VLOOKUP(C11,'📋 Tabela de Alimentos'!$B$7:$J$300,5,0)*E11/100,0) -> 0.48 | I11: =IFERROR(VLOOKUP(C11,'📋 Tabela de Alimentos'!$B$7:$J$300,6,0)*E11/100,0) -> 1.8 | J11: =IFERROR(VLOOKUP(C11,'📋 Tabela de Alimentos'!$B$7:$J$300,7,0)*E11/100,0) -> 0 | K11: =IFERROR(F11/$F$4,0) -> 0.0114 | L11: ~1 col. sopa cheia
B12: 4 | C12: Queijo mussarela | D12: ☀️ Café da Manhã | E12: 20 | F12: =IFERROR(VLOOKUP(C12,'📋 Tabela de Alimentos'!$B$7:$J$300,3,0)*E12/100,0) -> 57.8 | G12: =IFERROR(VLOOKUP(C12,'📋 Tabela de Alimentos'!$B$7:$J$300,4,0)*E12/100,0) -> 3.6 | H12: =IFERROR(VLOOKUP(C12,'📋 Tabela de Alimentos'!$B$7:$J$300,5,0)*E12/100,0) -> 0.52 | I12: =IFERROR(VLOOKUP(C12,'📋 Tabela de Alimentos'!$B$7:$J$300,6,0)*E12/100,0) -> 4.58 | J12: =IFERROR(VLOOKUP(C12,'📋 Tabela de Alimentos'!$B$7:$J$300,7,0)*E12/100,0) -> 0 | K12: =IFERROR(F12/$F$4,0) -> 0.0289 | L12: 1 fatia fina
B13: 5 | C13: Peito de peru fatiado | D13: ☀️ Café da Manhã | E13: 15 | F13: =IFERROR(VLOOKUP(C13,'📋 Tabela de Alimentos'!$B$7:$J$300,3,0)*E13/100,0) -> 16.35 | G13: =IFERROR(VLOOKUP(C13,'📋 Tabela de Alimentos'!$B$7:$J$300,4,0)*E13/100,0) -> 2.61 | H13: =IFERROR(VLOOKUP(C13,'📋 Tabela de Alimentos'!$B$7:$J$300,5,0)*E13/100,0) -> 0.285 | I13: =IFERROR(VLOOKUP(C13,'📋 Tabela de Alimentos'!$B$7:$J$300,6,0)*E13/100,0) -> 0.54 | J13: =IFERROR(VLOOKUP(C13,'📋 Tabela de Alimentos'!$B$7:$J$300,7,0)*E13/100,0) -> 0 | K13: =IFERROR(F13/$F$4,0) -> 0.008175 | L13: 1 fatia
B14: 6 | C14: Ovo inteiro cozido | D14: ☀️ Café da Manhã | E14: 100 | F14: =IFERROR(VLOOKUP(C14,'📋 Tabela de Alimentos'!$B$7:$J$300,3,0)*E14/100,0) -> 146 | G14: =IFERROR(VLOOKUP(C14,'📋 Tabela de Alimentos'!$B$7:$J$300,4,0)*E14/100,0) -> 13.3 | H14: =IFERROR(VLOOKUP(C14,'📋 Tabela de Alimentos'!$B$7:$J$300,5,0)*E14/100,0) -> 0.6 | I14: =IFERROR(VLOOKUP(C14,'📋 Tabela de Alimentos'!$B$7:$J$300,6,0)*E14/100,0) -> 10 | J14: =IFERROR(VLOOKUP(C14,'📋 Tabela de Alimentos'!$B$7:$J$300,7,0)*E14/100,0) -> 0 | K14: =IFERROR(F14/$F$4,0) -> 0.073 | L14: 2 ovos ≈ 100g
B15: 7 | C15: Maçã com casca | D15: ☀️ Café da Manhã | E15: 120 | F15: =IFERROR(VLOOKUP(C15,'📋 Tabela de Alimentos'!$B$7:$J$300,3,0)*E15/100,0) -> 67.2 | G15: =IFERROR(VLOOKUP(C15,'📋 Tabela de Alimentos'!$B$7:$J$300,4,0)*E15/100,0) -> 0.36 | H15: =IFERROR(VLOOKUP(C15,'📋 Tabela de Alimentos'!$B$7:$J$300,5,0)*E15/100,0) -> 17.88 | I15: =IFERROR(VLOOKUP(C15,'📋 Tabela de Alimentos'!$B$7:$J$300,6,0)*E15/100,0) -> 0.12 | J15: =IFERROR(VLOOKUP(C15,'📋 Tabela de Alimentos'!$B$7:$J$300,7,0)*E15/100,0) -> 2.16 | K15: =IFERROR(F15/$F$4,0) -> 0.0336 | L15: 1 maçã média
B16: 8 | C16: Creatina monohidratada | D16: ☀️ Café da Manhã | E16: 6 | F16: =IFERROR(VLOOKUP(C16,'📋 Tabela de Alimentos'!$B$7:$J$300,3,0)*E16/100,0) -> 0 | G16: =IFERROR(VLOOKUP(C16,'📋 Tabela de Alimentos'!$B$7:$J$300,4,0)*E16/100,0) -> 0 | H16: =IFERROR(VLOOKUP(C16,'📋 Tabela de Alimentos'!$B$7:$J$300,5,0)*E16/100,0) -> 0 | I16: =IFERROR(VLOOKUP(C16,'📋 Tabela de Alimentos'!$B$7:$J$300,6,0)*E16/100,0) -> 0 | J16: =IFERROR(VLOOKUP(C16,'📋 Tabela de Alimentos'!$B$7:$J$300,7,0)*E16/100,0) -> 0 | K16: =IFERROR(F16/$F$4,0) -> 0 | L16: 6g (2 doses)
B17: 🍌 Lanche da Manhã
B18: 9 | C18: Maçã com casca | D18: 🍌 Lanche da Manhã | E18: 130 | F18: =IFERROR(VLOOKUP(C15,'📋 Tabela de Alimentos'!$B$7:$J$203,3,0)*E15/100,0) -> 67.2 | G18: =IFERROR(VLOOKUP(C15,'📋 Tabela de Alimentos'!$B$7:$J$203,4,0)*E15/100,0) -> 0.36 | H18: =IFERROR(VLOOKUP(C15,'📋 Tabela de Alimentos'!$B$7:$J$203,5,0)*E15/100,0) -> 17.88 | I18: =IFERROR(VLOOKUP(C15,'📋 Tabela de Alimentos'!$B$7:$J$203,6,0)*E15/100,0) -> 0.12 | J18: =IFERROR(VLOOKUP(C15,'📋 Tabela de Alimentos'!$B$7:$J$203,7,0)*E15/100,0) -> 2.16 | K18: =IFERROR(F15/$F$4,0) -> 0.0336
B19: 10 | C19: Pasta de amendoim integral | D19: 🍌 Lanche da Manhã | E19: 20 | F19: =IFERROR(VLOOKUP(C16,'📋 Tabela de Alimentos'!$B$7:$J$203,3,0)*E16/100,0) -> 0 | G19: =IFERROR(VLOOKUP(C16,'📋 Tabela de Alimentos'!$B$7:$J$203,4,0)*E16/100,0) -> 0 | H19: =IFERROR(VLOOKUP(C16,'📋 Tabela de Alimentos'!$B$7:$J$203,5,0)*E16/100,0) -> 0 | I19: =IFERROR(VLOOKUP(C16,'📋 Tabela de Alimentos'!$B$7:$J$203,6,0)*E16/100,0) -> 0 | J19: =IFERROR(VLOOKUP(C16,'📋 Tabela de Alimentos'!$B$7:$J$203,7,0)*E16/100,0) -> 0 | K19: =IFERROR(F16/$F$4,0) -> 0
B20: 🥃 Almoço
B21: 11 | C21: Arroz integral cozido | D21: 🥃 Almoço | E21: 120 | F21: =IFERROR(VLOOKUP(C18,'📋 Tabela de Alimentos'!$B$7:$J$203,3,0)*E18/100,0) -> 72.8 | G21: =IFERROR(VLOOKUP(C18,'📋 Tabela de Alimentos'!$B$7:$J$203,4,0)*E18/100,0) -> 0.39 | H21: =IFERROR(VLOOKUP(C18,'📋 Tabela de Alimentos'!$B$7:$J$203,5,0)*E18/100,0) -> 19.37 | I21: =IFERROR(VLOOKUP(C18,'📋 Tabela de Alimentos'!$B$7:$J$203,6,0)*E18/100,0) -> 0.13 | J21: =IFERROR(VLOOKUP(C18,'📋 Tabela de Alimentos'!$B$7:$J$203,7,0)*E18/100,0) -> 2.34 | K21: =IFERROR(F18/$F$4,0) -> 0.0336
B22: 12 | C22: Feijão carioca cozido | D22: 🥃 Almoço | E22: 80 | F22: =IFERROR(VLOOKUP(C19,'📋 Tabela de Alimentos'!$B$7:$J$203,3,0)*E19/100,0) -> 118.6 | G22: =IFERROR(VLOOKUP(C19,'📋 Tabela de Alimentos'!$B$7:$J$203,4,0)*E19/100,0) -> 5.66 | H22: =IFERROR(VLOOKUP(C19,'📋 Tabela de Alimentos'!$B$7:$J$203,5,0)*E19/100,0) -> 3.98 | I22: =IFERROR(VLOOKUP(C19,'📋 Tabela de Alimentos'!$B$7:$J$203,6,0)*E19/100,0) -> 9.84 | J22: =IFERROR(VLOOKUP(C19,'📋 Tabela de Alimentos'!$B$7:$J$203,7,0)*E19/100,0) -> 1.5 | K22: =IFERROR(F19/$F$4,0) -> 0
B23: 13 | C23: Frango filé grelhado | D23: 🥃 Almoço | E23: 120 | F23: =IFERROR(VLOOKUP(C20,'📋 Tabela de Alimentos'!$B$7:$J$203,3,0)*E20/100,0) -> 0 | G23: =IFERROR(VLOOKUP(C20,'📋 Tabela de Alimentos'!$B$7:$J$203,4,0)*E20/100,0) -> 0 | H23: =IFERROR(VLOOKUP(C20,'📋 Tabela de Alimentos'!$B$7:$J$203,5,0)*E20/100,0) -> 0 | I23: =IFERROR(VLOOKUP(C20,'📋 Tabela de Alimentos'!$B$7:$J$203,6,0)*E20/100,0) -> 0 | J23: =IFERROR(VLOOKUP(C20,'📋 Tabela de Alimentos'!$B$7:$J$203,7,0)*E20/100,0) -> 0 | K23: =IFERROR(F20/$F$4,0) -> 0
B24: 14 | C24: Brócolis cozido | D24: 🥃 Almoço | E24: 80 | F24: =IFERROR(VLOOKUP(C21,'📋 Tabela de Alimentos'!$B$7:$J$203,3,0)*E21/100,0) -> 148.8 | G24: =IFERROR(VLOOKUP(C21,'📋 Tabela de Alimentos'!$B$7:$J$203,4,0)*E21/100,0) -> 3.12 | H24: =IFERROR(VLOOKUP(C21,'📋 Tabela de Alimentos'!$B$7:$J$203,5,0)*E21/100,0) -> 30.96 | I24: =IFERROR(VLOOKUP(C21,'📋 Tabela de Alimentos'!$B$7:$J$203,6,0)*E21/100,0) -> 1.2 | J24: =IFERROR(VLOOKUP(C21,'📋 Tabela de Alimentos'!$B$7:$J$203,7,0)*E21/100,0) -> 3.24 | K24: =IFERROR(F21/$F$4,0) -> 0.0364
B25: 15 | C25: Cenoura crua | D25: 🥃 Almoço | E25: 30 | F25: =IFERROR(VLOOKUP(C22,'📋 Tabela de Alimentos'!$B$7:$J$203,3,0)*E22/100,0) -> 60.8 | G25: =IFERROR(VLOOKUP(C22,'📋 Tabela de Alimentos'!$B$7:$J$203,4,0)*E22/100,0) -> 3.84 | H25: =IFERROR(VLOOKUP(C22,'📋 Tabela de Alimentos'!$B$7:$J$203,5,0)*E22/100,0) -> 10.4 | I25: =IFERROR(VLOOKUP(C22,'📋 Tabela de Alimentos'!$B$7:$J$203,6,0)*E22/100,0) -> 0.4 | J25: =IFERROR(VLOOKUP(C22,'📋 Tabela de Alimentos'!$B$7:$J$203,7,0)*E22/100,0) -> 6.8 | K25: =IFERROR(F22/$F$4,0) -> 0.0593
B26: 16 | C26: Azeite de oliva extra virgem | D26: 🥃 Almoço | E26: 8 | F26: =IFERROR(VLOOKUP(C23,'📋 Tabela de Alimentos'!$B$7:$J$203,3,0)*E23/100,0) -> 195.6 | G26: =IFERROR(VLOOKUP(C23,'📋 Tabela de Alimentos'!$B$7:$J$203,4,0)*E23/100,0) -> 37.8 | H26: =IFERROR(VLOOKUP(C23,'📋 Tabela de Alimentos'!$B$7:$J$203,5,0)*E23/100,0) -> 0 | I26: =IFERROR(VLOOKUP(C23,'📋 Tabela de Alimentos'!$B$7:$J$203,6,0)*E23/100,0) -> 4.44 | J26: =IFERROR(VLOOKUP(C23,'📋 Tabela de Alimentos'!$B$7:$J$203,7,0)*E23/100,0) -> 0 | K26: =IFERROR(F23/$F$4,0) -> 0
B27: 17 | C27: Laranja pera | D27: 🥃 Almoço | E27: 130 | F27: =IFERROR(VLOOKUP(C24,'📋 Tabela de Alimentos'!$B$7:$J$203,3,0)*E24/100,0) -> 17.6 | G27: =IFERROR(VLOOKUP(C24,'📋 Tabela de Alimentos'!$B$7:$J$203,4,0)*E24/100,0) -> 2.08 | H27: =IFERROR(VLOOKUP(C24,'📋 Tabela de Alimentos'!$B$7:$J$203,5,0)*E24/100,0) -> 2.8 | I27: =IFERROR(VLOOKUP(C24,'📋 Tabela de Alimentos'!$B$7:$J$203,6,0)*E24/100,0) -> 0.24 | J27: =IFERROR(VLOOKUP(C24,'📋 Tabela de Alimentos'!$B$7:$J$203,7,0)*E24/100,0) -> 2.4 | K27: =IFERROR(F24/$F$4,0) -> 0.0744
B28: 🍵 Lanche da Tarde
B29: 18 | C29: Pão integral | D29: 🍵 Lanche da Tarde | E29: 50 | F29: =IFERROR(VLOOKUP(C26,'📋 Tabela de Alimentos'!$B$7:$J$203,3,0)*E26/100,0) -> 70.72 | G29: =IFERROR(VLOOKUP(C26,'📋 Tabela de Alimentos'!$B$7:$J$203,4,0)*E26/100,0) -> 0 | H29: =IFERROR(VLOOKUP(C26,'📋 Tabela de Alimentos'!$B$7:$J$203,5,0)*E26/100,0) -> 0 | I29: =IFERROR(VLOOKUP(C26,'📋 Tabela de Alimentos'!$B$7:$J$203,6,0)*E26/100,0) -> 8 | J29: =IFERROR(VLOOKUP(C26,'📋 Tabela de Alimentos'!$B$7:$J$203,7,0)*E26/100,0) -> 0 | K29: =IFERROR(F26/$F$4,0) -> 0.0978
B30: 19 | C30: Queijo cottage | D30: 🍵 Lanche da Tarde | E30: 50 | F30: =IFERROR(VLOOKUP(C27,'📋 Tabela de Alimentos'!$B$7:$J$203,3,0)*E27/100,0) -> 59.8 | G30: =IFERROR(VLOOKUP(C27,'📋 Tabela de Alimentos'!$B$7:$J$203,4,0)*E27/100,0) -> 1.17 | H30: =IFERROR(VLOOKUP(C27,'📋 Tabela de Alimentos'!$B$7:$J$203,5,0)*E27/100,0) -> 14.95 | I30: =IFERROR(VLOOKUP(C27,'📋 Tabela de Alimentos'!$B$7:$J$203,6,0)*E27/100,0) -> 0.13 | J30: =IFERROR(VLOOKUP(C27,'📋 Tabela de Alimentos'!$B$7:$J$203,7,0)*E27/100,0) -> 2.86 | K30: =IFERROR(F27/$F$4,0) -> 0.0088
B31: 20 | C31: Morango | D31: 🍵 Lanche da Tarde | E31: 80 | F31: =IFERROR(VLOOKUP(C28,'📋 Tabela de Alimentos'!$B$7:$J$203,3,0)*E28/100,0) -> 0 | G31: =IFERROR(VLOOKUP(C28,'📋 Tabela de Alimentos'!$B$7:$J$203,4,0)*E28/100,0) -> 0 | H31: =IFERROR(VLOOKUP(C28,'📋 Tabela de Alimentos'!$B$7:$J$203,5,0)*E28/100,0) -> 0 | I31: =IFERROR(VLOOKUP(C28,'📋 Tabela de Alimentos'!$B$7:$J$203,6,0)*E28/100,0) -> 0 | J31: =IFERROR(VLOOKUP(C28,'📋 Tabela de Alimentos'!$B$7:$J$203,7,0)*E28/100,0) -> 0 | K31: =IFERROR(F28/$F$4,0) -> 0
B32: 21 | C32: Chá verde (infusão) | D32: 🍵 Lanche da Tarde | E32: 200 | F32: =IFERROR(VLOOKUP(C29,'📋 Tabela de Alimentos'!$B$7:$J$203,3,0)*E29/100,0) -> 126.5 | G32: =IFERROR(VLOOKUP(C29,'📋 Tabela de Alimentos'!$B$7:$J$203,4,0)*E29/100,0) -> 4.4 | H32: =IFERROR(VLOOKUP(C29,'📋 Tabela de Alimentos'!$B$7:$J$203,5,0)*E29/100,0) -> 23.35 | I32: =IFERROR(VLOOKUP(C29,'📋 Tabela de Alimentos'!$B$7:$J$203,6,0)*E29/100,0) -> 1.75 | J32: =IFERROR(VLOOKUP(C29,'📋 Tabela de Alimentos'!$B$7:$J$203,7,0)*E29/100,0) -> 2.85 | K32: =IFERROR(F29/$F$4,0) -> 0.03536
B33: 🌙 Jantar
B34: 22 | C34: Tilápia grelhada | D34: 🌙 Jantar | E34: 130 | F34: =IFERROR(VLOOKUP(C31,'📋 Tabela de Alimentos'!$B$7:$J$203,3,0)*E31/100,0) -> 24 | G34: =IFERROR(VLOOKUP(C31,'📋 Tabela de Alimentos'!$B$7:$J$203,4,0)*E31/100,0) -> 0.64 | H34: =IFERROR(VLOOKUP(C31,'📋 Tabela de Alimentos'!$B$7:$J$203,5,0)*E31/100,0) -> 5.68 | I34: =IFERROR(VLOOKUP(C31,'📋 Tabela de Alimentos'!$B$7:$J$203,6,0)*E31/100,0) -> 0.24 | J34: =IFERROR(VLOOKUP(C31,'📋 Tabela de Alimentos'!$B$7:$J$203,7,0)*E31/100,0) -> 1.68 | K34: =IFERROR(F31/$F$4,0) -> 0
B35: 23 | C35: Batata doce cozida | D35: 🌙 Jantar | E35: 100 | F35: =IFERROR(VLOOKUP(C32,'📋 Tabela de Alimentos'!$B$7:$J$203,3,0)*E32/100,0) -> 2 | G35: =IFERROR(VLOOKUP(C32,'📋 Tabela de Alimentos'!$B$7:$J$203,4,0)*E32/100,0) -> 0.4 | H35: =IFERROR(VLOOKUP(C32,'📋 Tabela de Alimentos'!$B$7:$J$203,5,0)*E32/100,0) -> 0.4 | I35: =IFERROR(VLOOKUP(C32,'📋 Tabela de Alimentos'!$B$7:$J$203,6,0)*E32/100,0) -> 0 | J35: =IFERROR(VLOOKUP(C32,'📋 Tabela de Alimentos'!$B$7:$J$203,7,0)*E32/100,0) -> 0 | K35: =IFERROR(F32/$F$4,0) -> 0.06325
B36: 24 | C36: Abobrinha cozida | D36: 🌙 Jantar | E36: 80 | F36: =IFERROR(VLOOKUP(C33,'📋 Tabela de Alimentos'!$B$7:$J$203,3,0)*E33/100,0) -> 0 | G36: =IFERROR(VLOOKUP(C33,'📋 Tabela de Alimentos'!$B$7:$J$203,4,0)*E33/100,0) -> 0 | H36: =IFERROR(VLOOKUP(C33,'📋 Tabela de Alimentos'!$B$7:$J$203,5,0)*E33/100,0) -> 0 | I36: =IFERROR(VLOOKUP(C33,'📋 Tabela de Alimentos'!$B$7:$J$203,6,0)*E33/100,0) -> 0 | J36: =IFERROR(VLOOKUP(C33,'📋 Tabela de Alimentos'!$B$7:$J$203,7,0)*E33/100,0) -> 0 | K36: =IFERROR(F33/$F$4,0) -> 0
B37: 25 | C37: Espinafre cru | D37: 🌙 Jantar | E37: 40 | F37: =IFERROR(VLOOKUP(C34,'📋 Tabela de Alimentos'!$B$7:$J$203,3,0)*E34/100,0) -> 166.4 | G37: =IFERROR(VLOOKUP(C34,'📋 Tabela de Alimentos'!$B$7:$J$203,4,0)*E34/100,0) -> 34.06 | H37: =IFERROR(VLOOKUP(C34,'📋 Tabela de Alimentos'!$B$7:$J$203,5,0)*E34/100,0) -> 0 | I37: =IFERROR(VLOOKUP(C34,'📋 Tabela de Alimentos'!$B$7:$J$203,6,0)*E34/100,0) -> 3.38 | J37: =IFERROR(VLOOKUP(C34,'📋 Tabela de Alimentos'!$B$7:$J$203,7,0)*E34/100,0) -> 0 | K37: =IFERROR(F34/$F$4,0) -> 0.012
B38: 26 | C38: Tomate cru | D38: 🌙 Jantar | E38: 60 | F38: =IFERROR(VLOOKUP(C35,'📋 Tabela de Alimentos'!$B$7:$J$203,3,0)*E35/100,0) -> 110 | G38: =IFERROR(VLOOKUP(C35,'📋 Tabela de Alimentos'!$B$7:$J$203,4,0)*E35/100,0) -> 1.4 | H38: =IFERROR(VLOOKUP(C35,'📋 Tabela de Alimentos'!$B$7:$J$203,5,0)*E35/100,0) -> 26 | I38: =IFERROR(VLOOKUP(C35,'📋 Tabela de Alimentos'!$B$7:$J$203,6,0)*E35/100,0) -> 0.1 | J38: =IFERROR(VLOOKUP(C35,'📋 Tabela de Alimentos'!$B$7:$J$203,7,0)*E35/100,0) -> 2.7 | K38: =IFERROR(F35/$F$4,0) -> 0.001
B39: 27 | C39: Azeite de oliva extra virgem | D39: 🌙 Jantar | E39: 5 | F39: =IFERROR(VLOOKUP(C36,'📋 Tabela de Alimentos'!$B$7:$J$203,3,0)*E36/100,0) -> 9.6 | G39: =IFERROR(VLOOKUP(C36,'📋 Tabela de Alimentos'!$B$7:$J$203,4,0)*E36/100,0) -> 0.64 | H39: =IFERROR(VLOOKUP(C36,'📋 Tabela de Alimentos'!$B$7:$J$203,5,0)*E36/100,0) -> 1.84 | I39: =IFERROR(VLOOKUP(C36,'📋 Tabela de Alimentos'!$B$7:$J$203,6,0)*E36/100,0) -> 0.08 | J39: =IFERROR(VLOOKUP(C36,'📋 Tabela de Alimentos'!$B$7:$J$203,7,0)*E36/100,0) -> 0.88 | K39: =IFERROR(F36/$F$4,0) -> 0
B40: 🌛 Ceia
B41: 28 | C41: Iogurte grego natural | D41: 🌛 Ceia | E41: 120 | F41: =IFERROR(VLOOKUP(C38,'📋 Tabela de Alimentos'!$B$7:$J$203,3,0)*E38/100,0) -> 10.8 | G41: =IFERROR(VLOOKUP(C38,'📋 Tabela de Alimentos'!$B$7:$J$203,4,0)*E38/100,0) -> 0.54 | H41: =IFERROR(VLOOKUP(C38,'📋 Tabela de Alimentos'!$B$7:$J$203,5,0)*E38/100,0) -> 2.1 | I41: =IFERROR(VLOOKUP(C38,'📋 Tabela de Alimentos'!$B$7:$J$203,6,0)*E38/100,0) -> 0.12 | J41: =IFERROR(VLOOKUP(C38,'📋 Tabela de Alimentos'!$B$7:$J$203,7,0)*E38/100,0) -> 0.72 | K41: =IFERROR(F38/$F$4,0) -> 0.055
B42: 29 | C42: Semente de chia | D42: 🌛 Ceia | E42: 10 | F42: =IFERROR(VLOOKUP(C39,'📋 Tabela de Alimentos'!$B$7:$J$203,3,0)*E39/100,0) -> 44.2 | G42: =IFERROR(VLOOKUP(C39,'📋 Tabela de Alimentos'!$B$7:$J$203,4,0)*E39/100,0) -> 0 | H42: =IFERROR(VLOOKUP(C39,'📋 Tabela de Alimentos'!$B$7:$J$203,5,0)*E39/100,0) -> 0 | I42: =IFERROR(VLOOKUP(C39,'📋 Tabela de Alimentos'!$B$7:$J$203,6,0)*E39/100,0) -> 5 | J42: =IFERROR(VLOOKUP(C39,'📋 Tabela de Alimentos'!$B$7:$J$203,7,0)*E39/100,0) -> 0 | K42: =IFERROR(F39/$F$4,0) -> 0.0048
...

Sheet 📊 Dashboard de Macros
B2: 📊 DASHBOARD DE MACRONUTRIENTES E SAÚDE NUTRICIONAL
B4: 🔥 CALORIAS CONSUMIDAS | C4: 🎯 META CALÓRICA | D4: 💪 PROTEÍNAS | E4: 🌾 CARBOIDRATOS | F4: 🥑 GORDURAS | G4: 🌿 FIBRAS
B5: ='🍽️ Plano do Dia'!F45 -> 1769.57 | C5: ='🍽️ Plano do Dia'!F4 -> 2000 | D5: ='🍽️ Plano do Dia'!G45 -> 122.095 | E5: ='🍽️ Plano do Dia'!H45 -> 208.775 | F5: ='🍽️ Plano do Dia'!I45 -> 53.76 | G5: ='🍽️ Plano do Dia'!J45 -> 33.44
B7: 🥧 DISTRIBUIÇÃO CALÓRICA POR MACRONUTRIENTE (meta: 50% carbs, 25% prot, 25% gord)
B8: Macro | C8: Consumido (g) | D8: Kcal do macro | E8: % das Kcal totais | F8: Meta % | G8: Status
B9: 💪 Proteínas | C9: ='🍽️ Plano do Dia'!G45 -> 122.095 | D9: =C9*4 -> 488.38 | E9: =IFERROR(D9/B5,0) -> 0.27598795 | F9: 25% | G9: =IF(ABS(E9-0.25)<0.05,"✅ Ideal",IF(E9<0.25,"🔽 Abaixo","🔼 Acima")) -> ✅ Ideal
B10: 🌾 Carboidratos | C10: ='🍽️ Plano do Dia'!H45 -> 208.775 | D10: =C10*4 -> 835.1 | E10: =IFERROR(D10/B5,0) -> 0.47192256 | F10: 50% | G10: =IF(ABS(E10-0.5)<0.05,"✅ Ideal",IF(E10<0.5,"🔽 Abaixo","🔼 Acima")) -> ✅ Ideal
B11: 🥑 Gorduras | C11: ='🍽️ Plano do Dia'!I45 -> 53.76 | D11: =C11*9 -> 483.84 | E11: =IFERROR(D11/B5,0) -> 0.27342236 | F11: 25% | G11: =IF(ABS(E11-0.25)<0.05,"✅ Ideal",IF(E11<0.25,"🔽 Abaixo","🔼 Acima")) -> ✅ Ideal
B13: 🏥 INDICADORES DE SAÚDE NUTRICIONAL
B14: Indicador | C14: Valor Atual | D14: Meta/Recomendação | E14: Status | F14: Dica
B15: 🔥 Balanço Calórico | C15: ='🍽️ Plano do Dia'!F42-'🍽️ Plano do Dia'!F4 -> -1955.8 | D15: 0 kcal (equilíbrio) | E15: =IF(ABS('🍽️ Plano do Dia'!F42-'🍽️ Plano do Dia'!F4)<=100,"✅ Equilibrado",IF('🍽️ Plano do Dia'!F42<'🍽️ Plano do Dia'!F4,"⬇️ Déficit","⬆️ Superávit")) -> ⬇️ Déficit | F15: Déficit de 300-500kcal para emagrecer com saúde
B16: 💪 Proteína/kg peso | C16: =IFERROR('🍽️ Plano do Dia'!G42/'🍽️ Plano do Dia'!H4,0) -> 0 | D16: 1.6–2.2 g/kg (atletas) | E16: =IF('🍽️ Plano do Dia'!G42/'🍽️ Plano do Dia'!H4>=1.6,"✅ Adequado","⚠️ Aumentar proteína") -> ⚠️ Aumentar proteína | F16: Inclua carnes, ovos, leguminosas
B17: 🌿 Fibras totais | C17: ='🍽️ Plano do Dia'!J42 -> 0 | D17: ≥25g/dia (OMS) | E17: =IF('🍽️ Plano do Dia'!J42>=25,"✅ Adequado",IF('🍽️ Plano do Dia'!J42>=15,"🟡 Regular","🔴 Insuficiente")) -> 🔴 Insuficiente | F17: Aumente frutas, verduras e grãos integrais
B18: 🥑 Gordura total | C18: ='🍽️ Plano do Dia'!I42 -> 5 | D18: 20–35% das kcal totais | E18: =IF('🍽️ Plano do Dia'!I42*9/'🍽️ Plano do Dia'!F42<=0.35,"✅ Adequado","⚠️ Revisar gorduras") -> ⚠️ Revisar gorduras | F18: Prefira azeite, abacate e oleaginosas
B19: 🥗 Variedade vegetal | C19: =COUNTIFS('🍽️ Plano do Dia'!D8:D40,"*Almoço*",'🍽️ Plano do Dia'!C8:C40,"<>") -> 7 | D19: ≥5 porções de vegetais/dia | E19: "Acompanhe sua variedade" | F19: Diversifique cores no prato
B21: 📏 GUIA DE PORÇÕES RECOMENDADAS (Dieta de 2000 kcal)
B22: Grupo Alimentar | C22: Porções/dia | D22: Exemplo de 1 porção | E22: Calorias aprox. | F22: Dica
B23: 🌾 Cereais e tubérculos | C23: 6 porções | D23: 4 colh. arroz cozido = 100g ou 1 fatia pão integral | E23: ~100–130 kcal | F23: Prefira integrais
B24: 🥩 Carnes e ovos | C24: 1–2 porções | D24: 1 filé de frango = 100g ou 2 ovos mexidos | E24: ~150–200 kcal | F24: Carnes magras grelhadas
B25: 🫘 Leguminosas | C25: 1 porção | D25: 1 concha feijão = 80g ou ½ xíc grão-de-bico | E25: ~60–80 kcal | F25: Rico em fibras e ferro
B26: 🥛 Laticínios | C26: 3 porções | D26: 1 copo leite 200ml ou 1 pot. iogurte grego 100g | E26: ~70–100 kcal | F26: Fontes de cálcio
B27: 🥗 Vegetais e saladas | C27: 3+ porções | D27: 1 prato raso de salada crua = 60–100g | E27: ~10–25 kcal | F27: Quanto mais colorido melhor
B28: 🍎 Frutas | C28: 3 porções | D28: 1 fruta média ou 1 xícara de morangos = 100–130g | E28: ~40–70 kcal | F28: Variar tipos e cores
B29: 🥜 Gorduras e oleaginosas | C29: 1 porção | D29: 1 col. sobr. azeite = 10g ou 5 castanhas-do-Pará = 15g | E29: ~70–100 kcal | F29: Gorduras boas, com moderação
B30: 💧 Líquidos | C30: 8 copos/dia | D30: 1 copo água 250ml | E30: 0 kcal | F30: Beba 2–3 litros/dia

Sheet 🔧 Listas
A1: ALIMENTOS
A2: Arroz branco cozido
A3: Arroz integral cozido
A4: Macarrão cozido
A5: Macarrão integral cozido
A6: Pão francês
A7: Pão integral
A8: Aveia em flocos
A9: Batata inglesa cozida
A10: Batata doce cozida
A11: Mandioca cozida
A12: Tapioca (goma)
... A132: Canela em pó
