Workbook

Sheet _Listas
C1: Alimento | D1: Kcal/100g | E1: Prot | F1: Carb | G1: Gord | H1: Fibra
A2: Abacate | C2: Abacate | D2: 160 | E2: 1.2 | F2: 6 | G2: 14.7 | H2: 6.2
A3: Abacaxi | C3: Abacaxi | D3: 48 | E3: 0.9 | F3: 12.3 | G3: 0.1 | H3: 1
A4: Aipim cozido | C4: Aipim cozido | D4: 149 | E4: 0.9 | F4: 35.3 | G4: 0.3 | H4: 1.9
A5: Alcatra grelhada | C5: Alcatra grelhada | D5: 237 | E5: 32.8 | F5: 0 | G5: 11.4 | H5: 0
A6: Alcatra suína assada | C6: Alcatra suína assada | D6: 245 | E6: 30 | F6: 0 | G6: 14 | H6: 0
A7: Alface crespa | C7: Alface crespa | D7: 11 | E7: 1.3 | F7: 1.7 | G7: 0.2 | H7: 1.8
A8: Ameixa | C8: Ameixa | D8: 55 | E8: 0.8 | F8: 13.9 | G8: 0.2 | H8: 1.7
A9: Arroz branco cozido | C9: Arroz branco cozido | D9: 128 | E9: 2.5 | F9: 28.1 | G9: 0.2 | H9: 1.6
A10: Arroz integral cozido | C10: Arroz integral cozido | D10: 124 | E10: 2.6 | F10: 25.8 | G10: 1 | H10: 2.7
A11: Atum enlatado ao natural | C11: Atum enlatado ao natural | D11: 119 | E11: 26.3 | F11: 0 | G11: 1.3 | H11: 0
A12: Banana | C12: Banana | D12: 92 | E12: 1.3 | F12: 23.8 | G12: 0.1 | H12: 1.9
A13: Batata doce assada | C13: Batata doce assada | D13: 118 | E13: 1.6 | F13: 27.5 | G13: 0.1 | H13: 3
... A80: Yopro 15g High Protein | C80: Yopro 15g High Protein | D80: 67 | E80: 6.7 | F80: 10 | G80: 0 | H80: 0

Sheet SEG
B2: 🍽️ PLANO ALIMENTAR · Segunda-feira 🔵 · (=Qua e Sex)
B3: ▼ Clique na seta ▼ em cada alimento para trocar · Edite a porção (g) para recalcular as calorias automaticamente
B4: Meta Kcal/dia: | C4: 2000 | D4: Peso (kg): | E4: 70 | F4: Objetivo: | G4: Emagrecimento
B6: Refeição / Horário | C6: Alimento ▼ | D6: Porção (g) | E6: Kcal | F6: Prot. (g) | G6: Carb. (g) | H6: Gord. (g) | I6: Medida caseira
B8: ☕ Café da Manhã 08:00h
B9: ☕ Café da Manhã | C9: Café sem açúcar | D9: 200 | E9: =IFERROR(VLOOKUP(C9,_Listas!$C$2:$H$80,2,0)*D9/100,0) -> 4 | F9: =IFERROR(VLOOKUP(C9,_Listas!$C$2:$H$80,3,0)*D9/100,0) -> 0.6 | G9: =IFERROR(VLOOKUP(C9,_Listas!$C$2:$H$80,4,0)*D9/100,0) -> 0 | H9: =IFERROR(VLOOKUP(C9,_Listas!$C$2:$H$80,5,0)*D9/100,0) -> 0 | I9: 200 ml
C10: Pão francês | D10: 60 | E10: =IFERROR(VLOOKUP(C10,_Listas!$C$2:$H$80,2,0)*D10/100,0) -> 180 | F10: =IFERROR(VLOOKUP(C10,_Listas!$C$2:$H$80,3,0)*D10/100,0) -> 4.8 | G10: =IFERROR(VLOOKUP(C10,_Listas!$C$2:$H$80,4,0)*D10/100,0) -> 35.16 | H10: =IFERROR(VLOOKUP(C10,_Listas!$C$2:$H$80,5,0)*D10/100,0) -> 1.86 | I10: 1 unidade
C11: Requeijão | D11: 15 | E11: =IFERROR(VLOOKUP(C11,_Listas!$C$2:$H$80,2,0)*D11/100,0) -> 36 | F11: =IFERROR(VLOOKUP(C11,_Listas!$C$2:$H$80,3,0)*D11/100,0) -> 1.05 | G11: =IFERROR(VLOOKUP(C11,_Listas!$C$2:$H$80,4,0)*D11/100,0) -> 0.525 | H11: =IFERROR(VLOOKUP(C11,_Listas!$C$2:$H$80,5,0)*D11/100,0) -> 3.3 | I11: 1 col. sopa
C12: Queijo mussarela | D12: 20 | E12: =IFERROR(VLOOKUP(C12,_Listas!$C$2:$H$80,2,0)*D12/100,0) -> 57.8 | F12: =IFERROR(VLOOKUP(C12,_Listas!$C$2:$H$80,3,0)*D12/100,0) -> 3.6 | G12: =IFERROR(VLOOKUP(C12,_Listas!$C$2:$H$80,4,0)*D12/100,0) -> 0.52 | H12: =IFERROR(VLOOKUP(C12,_Listas!$C$2:$H$80,5,0)*D12/100,0) -> 4.58 | I12: 1 fatia
C13: Banana | D13: 70 | E13: =IFERROR(VLOOKUP(C13,_Listas!$C$2:$H$80,2,0)*D13/100,0) -> 64.4 | F13: =IFERROR(VLOOKUP(C13,_Listas!$C$2:$H$80,3,0)*D13/100,0) -> 0.91 | G13: =IFERROR(VLOOKUP(C13,_Listas!$C$2:$H$80,4,0)*D13/100,0) -> 16.66 | H13: =IFERROR(VLOOKUP(C13,_Listas!$C$2:$H$80,5,0)*D13/100,0) -> 0.07 | I13: ½ unidade méd.
C14: Creatina monohidratada | D14: 6 | E14: =IFERROR(VLOOKUP(C14,_Listas!$C$2:$H$80,2,0)*D14/100,0) -> 0 | F14: =IFERROR(VLOOKUP(C14,_Listas!$C$2:$H$80,3,0)*D14/100,0) -> 0 | G14: =IFERROR(VLOOKUP(C14,_Listas!$C$2:$H$80,4,0)*D14/100,0) -> 0 | H14: =IFERROR(VLOOKUP(C14,_Listas!$C$2:$H$80,5,0)*D14/100,0) -> 0 | I14: 2 doses
B15: Subtotal ☕ Café da Manhã | D15: =SUM(D9:D14) -> 371 | E15: =SUM(E9:E14) -> 342.2 | F15: =SUM(F9:F14) -> 10.96 | G15: =SUM(G9:G14) -> 52.865 | H15: =SUM(H9:H14) -> 9.81
B17: 🍌 Lanche 10:00h
B18: 🍌 Lanche | C18: Yopro 15g High Protein | D18: 300 | E18: =IFERROR(VLOOKUP(C18,_Listas!$C$2:$H$80,2,0)*D18/100,0) -> 201 | F18: =IFERROR(VLOOKUP(C18,_Listas!$C$2:$H$80,3,0)*D18/100,0) -> 20.1 | G18: =IFERROR(VLOOKUP(C18,_Listas!$C$2:$H$80,4,0)*D18/100,0) -> 30 | H18: =IFERROR(VLOOKUP(C18,_Listas!$C$2:$H$80,5,0)*D18/100,0) -> 0 | I18: 1 unidade
B19: Subtotal 🍌 Lanche | D19: =SUM(D18:D18) -> 300 | E19: =SUM(E18:E18) -> 201 | F19: =SUM(F18:F18) -> 20.1 | G19: =SUM(G18:G18) -> 30 | H19: =SUM(H18:H18) -> 0
B21: 🥗 Almoço 13:00h
B22: 🥗 Almoço | C22: Batata inglesa assada | D22: 150 | E22: =IFERROR(VLOOKUP(C22,_Listas!$C$2:$H$80,2,0)*D22/100,0) -> 139.5 | F22: =IFERROR(VLOOKUP(C22,_Listas!$C$2:$H$80,3,0)*D22/100,0) -> 3.75 | G22: =IFERROR(VLOOKUP(C22,_Listas!$C$2:$H$80,4,0)*D22/100,0) -> 31.5 | H22: =IFERROR(VLOOKUP(C22,_Listas!$C$2:$H$80,5,0)*D22/100,0) -> 0.15 | I22: 1 unid. média
C23: Feijão preto cozido | D23: 120 | E23: =IFERROR(VLOOKUP(C23,_Listas!$C$2:$H$80,2,0)*D23/100,0) -> 92.4 | F23: =IFERROR(VLOOKUP(C23,_Listas!$C$2:$H$80,3,0)*D23/100,0) -> 5.4 | G23: =IFERROR(VLOOKUP(C23,_Listas!$C$2:$H$80,4,0)*D23/100,0) -> 16.32 | H23: =IFERROR(VLOOKUP(C23,_Listas!$C$2:$H$80,5,0)*D23/100,0) -> 0.6 | I23: 1 concha
C24: Moranga cozida | D24: 100 | E24: =IFERROR(VLOOKUP(C24,_Listas!$C$2:$H$80,2,0)*D24/100,0) -> 26 | F24: =IFERROR(VLOOKUP(C24,_Listas!$C$2:$H$80,3,0)*D24/100,0) -> 0.7 | G24: =IFERROR(VLOOKUP(C24,_Listas!$C$2:$H$80,4,0)*D24/100,0) -> 6 | H24: =IFERROR(VLOOKUP(C24,_Listas!$C$2:$H$80,5,0)*D24/100,0) -> 0.1 | I24: 1 porção
C25: Sobrecoxa de frango grelhada | D25: 150 | E25: =IFERROR(VLOOKUP(C25,_Listas!$C$2:$H$80,2,0)*D25/100,0) -> 322.5 | F25: =IFERROR(VLOOKUP(C25,_Listas!$C$2:$H$80,3,0)*D25/100,0) -> 31.5 | G25: =IFERROR(VLOOKUP(C25,_Listas!$C$2:$H$80,4,0)*D25/100,0) -> 0 | H25: =IFERROR(VLOOKUP(C25,_Listas!$C$2:$H$80,5,0)*D25/100,0) -> 21 | I25: 1 peça s/ osso
C26: Melancia | D26: 150 | E26: =IFERROR(VLOOKUP(C26,_Listas!$C$2:$H$80,2,0)*D26/100,0) -> 49.5 | F26: =IFERROR(VLOOKUP(C26,_Listas!$C$2:$H$80,3,0)*D26/100,0) -> 1.05 | G26: =IFERROR(VLOOKUP(C26,_Listas!$C$2:$H$80,4,0)*D26/100,0) -> 12 | H26: =IFERROR(VLOOKUP(C26,_Listas!$C$2:$H$80,5,0)*D26/100,0) -> 0.3 | I26: 1 fatia
B27: Subtotal 🥗 Almoço | D27: =SUM(D22:D26) -> 670 | E27: =SUM(E22:E26) -> 629.9 | F27: =SUM(F22:F26) -> 42.4 | G27: =SUM(G22:G26) -> 65.82 | H27: =SUM(H22:H26) -> 22.15
B29: ☕ Café da Tarde 18:00h
B30: ☕ Café da Tarde | C30: Café sem açúcar | D30: 200 | E30: =IFERROR(VLOOKUP(C30,_Listas!$C$2:$H$80,2,0)*D30/100,0) -> 4 | F30: =IFERROR(VLOOKUP(C30,_Listas!$C$2:$H$80,3,0)*D30/100,0) -> 0.6 | G30: =IFERROR(VLOOKUP(C30,_Listas!$C$2:$H$80,4,0)*D30/100,0) -> 0 | H30: =IFERROR(VLOOKUP(C30,_Listas!$C$2:$H$80,5,0)*D30/100,0) -> 0 | I30: 200 ml
C31: Pão francês | D31: 60 | E31: =IFERROR(VLOOKUP(C31,_Listas!$C$2:$H$80,2,0)*D31/100,0) -> 180 | F31: =IFERROR(VLOOKUP(C31,_Listas!$C$2:$H$80,3,0)*D31/100,0) -> 4.8 | G31: =IFERROR(VLOOKUP(C31,_Listas!$C$2:$H$80,4,0)*D31/100,0) -> 35.16 | H31: =IFERROR(VLOOKUP(C31,_Listas!$C$2:$H$80,5,0)*D31/100,0) -> 1.86 | I31: 1 unidade
C32: Filé de frango grelhado | D32: 50 | E32: =IFERROR(VLOOKUP(C32,_Listas!$C$2:$H$80,2,0)*D32/100,0) -> 81.5 | F32: =IFERROR(VLOOKUP(C32,_Listas!$C$2:$H$80,3,0)*D32/100,0) -> 15.75 | G32: =IFERROR(VLOOKUP(C32,_Listas!$C$2:$H$80,4,0)*D32/100,0) -> 0 | H32: =IFERROR(VLOOKUP(C32,_Listas!$C$2:$H$80,5,0)*D32/100,0) -> 1.85 | I32: ½ filé pequeno
C33: Melão | D33: 150 | E33: =IFERROR(VLOOKUP(C33,_Listas!$C$2:$H$80,2,0)*D33/100,0) -> 43.5 | F33: =IFERROR(VLOOKUP(C33,_Listas!$C$2:$H$80,3,0)*D33/100,0) -> 1.05 | G33: =IFERROR(VLOOKUP(C33,_Listas!$C$2:$H$80,4,0)*D33/100,0) -> 11.1 | H33: =IFERROR(VLOOKUP(C33,_Listas!$C$2:$H$80,5,0)*D33/100,0) -> 0.15 | I33: 1 fatia
B34: Subtotal ☕ Café da Tarde | D34: =SUM(D30:D33) -> 460 | E34: =SUM(E30:E33) -> 309 | F34: =SUM(F30:F33) -> 22.2 | G34: =SUM(G30:G33) -> 46.26 | H34: =SUM(H30:H33) -> 3.86
B36: 🌙 Jantar 20:30h
B37: 🌙 Jantar | C37: Arroz branco cozido | D37: 140 | E37: =IFERROR(VLOOKUP(C37,_Listas!$C$2:$H$80,2,0)*D37/100,0) -> 179.2 | F37: =IFERROR(VLOOKUP(C37,_Listas!$C$2:$H$80,3,0)*D37/100,0) -> 3.5 | G37: =IFERROR(VLOOKUP(C37,_Listas!$C$2:$H$80,4,0)*D37/100,0) -> 39.34 | H37: =IFERROR(VLOOKUP(C37,_Listas!$C$2:$H$80,5,0)*D37/100,0) -> 0.28 | I37: 4 col. sopa
C38: Feijão preto cozido | D38: 120 | E38: =IFERROR(VLOOKUP(C38,_Listas!$C$2:$H$80,2,0)*D38/100,0) -> 92.4 | F38: =IFERROR(VLOOKUP(C38,_Listas!$C$2:$H$80,3,0)*D38/100,0) -> 5.4 | G38: =IFERROR(VLOOKUP(C38,_Listas!$C$2:$H$80,4,0)*D38/100,0) -> 16.32 | H38: =IFERROR(VLOOKUP(C38,_Listas!$C$2:$H$80,5,0)*D38/100,0) -> 0.6 | I38: 1 concha
C39: Filé de frango grelhado | D39: 140 | E39: =IFERROR(VLOOKUP(C39,_Listas!$C$2:$H$80,2,0)*D39/100,0) -> 228.2 | F39: =IFERROR(VLOOKUP(C39,_Listas!$C$2:$H$80,3,0)*D39/100,0) -> 44.1 | G39: =IFERROR(VLOOKUP(C39,_Listas!$C$2:$H$80,4,0)*D39/100,0) -> 0 | H39: =IFERROR(VLOOKUP(C39,_Listas!$C$2:$H$80,5,0)*D39/100,0) -> 5.18 | I39: 1 filé médio
C40: Melão | D40: 150 | E40: =IFERROR(VLOOKUP(C40,_Listas!$C$2:$H$80,2,0)*D40/100,0) -> 43.5 | F40: =IFERROR(VLOOKUP(C40,_Listas!$C$2:$H$80,3,0)*D40/100,0) -> 1.05 | G40: =IFERROR(VLOOKUP(C40,_Listas!$C$2:$H$80,4,0)*D40/100,0) -> 11.1 | H40: =IFERROR(VLOOKUP(C40,_Listas!$C$2:$H$80,5,0)*D40/100,0) -> 0.15 | I40: 1 fatia
B41: Subtotal 🌙 Jantar | D41: =SUM(D37:D40) -> 550 | E41: =SUM(E37:E40) -> 543.3 | F41: =SUM(F37:F40) -> 54.05 | G41: =SUM(G37:G40) -> 66.76 | H41: =SUM(H37:H40) -> 6.21
B43: 🔄 Opção Jantar (alternativa)
B44: 🔄 Opção Jantar | C44: Suco de laranja natural | D44: 200 | E44: =IFERROR(VLOOKUP(C44,_Listas!$C$2:$H$80,2,0)*D44/100,0) -> 90 | F44: =IFERROR(VLOOKUP(C44,_Listas!$C$2:$H$80,3,0)*D44/100,0) -> 1.4 | G44: =IFERROR(VLOOKUP(C44,_Listas!$C$2:$H$80,4,0)*D44/100,0) -> 21.4 | H44: =IFERROR(VLOOKUP(C44,_Listas!$C$2:$H$80,5,0)*D44/100,0) -> 0.4 | I44: 1 copo
C45: Tapioca de goma | D45: 30 | E45: =IFERROR(VLOOKUP(C45,_Listas!$C$2:$H$80,2,0)*D45/100,0) -> 106.2 | F45: =IFERROR(VLOOKUP(C45,_Listas!$C$2:$H$80,3,0)*D45/100,0) -> 0.03 | G45: =IFERROR(VLOOKUP(C45,_Listas!$C$2:$H$80,4,0)*D45/100,0) -> 26.34 | H45: =IFERROR(VLOOKUP(C45,_Listas!$C$2:$H$80,5,0)*D45/100,0) -> 0.09 | I45: 1 tapioca peq.
C46: Ovo de galinha cozido | D46: 100 | E46: =IFERROR(VLOOKUP(C46,_Listas!$C$2:$H$80,2,0)*D46/100,0) -> 146 | F46: =IFERROR(VLOOKUP(C46,_Listas!$C$2:$H$80,3,0)*D46/100,0) -> 13.3 | G46: =IFERROR(VLOOKUP(C46,_Listas!$C$2:$H$80,4,0)*D46/100,0) -> 0.6 | H46: =IFERROR(VLOOKUP(C46,_Listas!$C$2:$H$80,5,0)*D46/100,0) -> 10 | I46: 2 unidades
C47: Queijo mussarela | D47: 20 | E47: =IFERROR(VLOOKUP(C47,_Listas!$C$2:$H$80,2,0)*D47/100,0) -> 57.8 | F47: =IFERROR(VLOOKUP(C47,_Listas!$C$2:$H$80,3,0)*D47/100,0) -> 3.6 | G47: =IFERROR(VLOOKUP(C47,_Listas!$C$2:$H$80,4,0)*D47/100,0) -> 0.52 | H47: =IFERROR(VLOOKUP(C47,_Listas!$C$2:$H$80,5,0)*D47/100,0) -> 4.58 | I47: 1 fatia
C48: Filé de frango grelhado | D48: 80 | E48: =IFERROR(VLOOKUP(C48,_Listas!$C$2:$H$80,2,0)*D48/100,0) -> 130.4 | F48: =IFERROR(VLOOKUP(C48,_Listas!$C$2:$H$80,3,0)*D48/100,0) -> 25.2 | G48: =IFERROR(VLOOKUP(C48,_Listas!$C$2:$H$80,4,0)*D48/100,0) -> 0 | H48: =IFERROR(VLOOKUP(C48,_Listas!$C$2:$H$80,5,0)*D48/100,0) -> 2.96 | I48: 1 filé pequeno
...

Sheet TER
B2: 🍽️ PLANO ALIMENTAR · Terça-feira 🟢 · (=Qui e Sab)
B3: ▼ Clique na seta ▼ em cada alimento para trocar · Edite a porção (g) para recalcular as calorias automaticamente
B4: Meta Kcal/dia: | C4: 2000 | D4: Peso (kg): | E4: 70 | F4: Objetivo: | G4: Emagrecimento
B6: Refeição / Horário | C6: Alimento ▼ | D6: Porção (g) | E6: Kcal | F6: Prot. (g) | G6: Carb. (g) | H6: Gord. (g) | I6: Medida caseira
B8: ☕ Café da Manhã 08:00h
B9: ☕ Café da Manhã | C9: Café sem açúcar | D9: 200 | E9: =IFERROR(VLOOKUP(C9,_Listas!$C$2:$H$80,2,0)*D9/100,0) -> 4 | F9: =IFERROR(VLOOKUP(C9,_Listas!$C$2:$H$80,3,0)*D9/100,0) -> 0.6 | G9: =IFERROR(VLOOKUP(C9,_Listas!$C$2:$H$80,4,0)*D9/100,0) -> 0 | H9: =IFERROR(VLOOKUP(C9,_Listas!$C$2:$H$80,5,0)*D9/100,0) -> 0 | I9: 200 ml
C10: Pão francês | D10: 60 | E10: =IFERROR(VLOOKUP(C10,_Listas!$C$2:$H$80,2,0)*D10/100,0) -> 180 | F10: =IFERROR(VLOOKUP(C10,_Listas!$C$2:$H$80,3,0)*D10/100,0) -> 4.8 | G10: =IFERROR(VLOOKUP(C10,_Listas!$C$2:$H$80,4,0)*D10/100,0) -> 35.16 | H10: =IFERROR(VLOOKUP(C10,_Listas!$C$2:$H$80,5,0)*D10/100,0) -> 1.86 | I10: 1 unidade
C11: Requeijão | D11: 15 | E11: =IFERROR(VLOOKUP(C11,_Listas!$C$2:$H$80,2,0)*D11/100,0) -> 36 | F11: =IFERROR(VLOOKUP(C11,_Listas!$C$2:$H$80,3,0)*D11/100,0) -> 1.05 | G11: =IFERROR(VLOOKUP(C11,_Listas!$C$2:$H$80,4,0)*D11/100,0) -> 0.525 | H11: =IFERROR(VLOOKUP(C11,_Listas!$C$2:$H$80,5,0)*D11/100,0) -> 3.3 | I11: 1 col. sopa
C12: Queijo mussarela | D12: 20 | E12: =IFERROR(VLOOKUP(C12,_Listas!$C$2:$H$80,2,0)*D12/100,0) -> 57.8 | F12: =IFERROR(VLOOKUP(C12,_Listas!$C$2:$H$80,3,0)*D12/100,0) -> 3.6 | G12: =IFERROR(VLOOKUP(C12,_Listas!$C$2:$H$80,4,0)*D12/100,0) -> 0.52 | H12: =IFERROR(VLOOKUP(C12,_Listas!$C$2:$H$80,5,0)*D12/100,0) -> 4.58 | I12: 1 fatia
C13: Peito de peru fatiado | D13: 15 | E13: =IFERROR(VLOOKUP(C13,_Listas!$C$2:$H$80,2,0)*D13/100,0) -> 16.35 | F13: =IFERROR(VLOOKUP(C13,_Listas!$C$2:$H$80,3,0)*D13/100,0) -> 2.61 | G13: =IFERROR(VLOOKUP(C13,_Listas!$C$2:$H$80,4,0)*D13/100,0) -> 0.285 | H13: =IFERROR(VLOOKUP(C13,_Listas!$C$2:$H$80,5,0)*D13/100,0) -> 0.54 | I13: 1 fatia
C14: Maçã com casca | D14: 120 | E14: =IFERROR(VLOOKUP(C14,_Listas!$C$2:$H$80,2,0)*D14/100,0) -> 67.2 | F14: =IFERROR(VLOOKUP(C14,_Listas!$C$2:$H$80,3,0)*D14/100,0) -> 0.36 | G14: =IFERROR(VLOOKUP(C14,_Listas!$C$2:$H$80,4,0)*D14/100,0) -> 17.88 | H14: =IFERROR(VLOOKUP(C14,_Listas!$C$2:$H$80,5,0)*D14/100,0) -> 0.12 | I14: 1 unid. média
C15: Creatina monohidratada | D15: 6 | E15: =IFERROR(VLOOKUP(C15,_Listas!$C$2:$H$80,2,0)*D15/100,0) -> 0 | F15: =IFERROR(VLOOKUP(C15,_Listas!$C$2:$H$80,3,0)*D15/100,0) -> 0 | G15: =IFERROR(VLOOKUP(C15,_Listas!$C$2:$H$80,4,0)*D15/100,0) -> 0 | H15: =IFERROR(VLOOKUP(C15,_Listas!$C$2:$H$80,5,0)*D15/100,0) -> 0 | I15: 2 doses
B16: Subtotal ☕ Café da Manhã | D16: =SUM(D9:D15) -> 436 | E16: =SUM(E9:E15) -> 361.35 | F16: =SUM(F9:F15) -> 13.02 | G16: =SUM(G9:G15) -> 54.37 | H16: =SUM(H9:H15) -> 10.4
B18: 🍌 Lanche 10:00h
B19: 🍌 Lanche | C19: Yopro 15g High Protein | D19: 300 | E19: =IFERROR(VLOOKUP(C19,_Listas!$C$2:$H$80,2,0)*D19/100,0) -> 201 | F19: =IFERROR(VLOOKUP(C19,_Listas!$C$2:$H$80,3,0)*D19/100,0) -> 20.1 | G19: =IFERROR(VLOOKUP(C19,_Listas!$C$2:$H$80,4,0)*D19/100,0) -> 30 | H19: =IFERROR(VLOOKUP(C19,_Listas!$C$2:$H$80,5,0)*D19/100,0) -> 0 | I19: 1 unidade
B20: Subtotal 🍌 Lanche | D20: =SUM(D19:D19) -> 300 | E20: =SUM(E19:E19) -> 201 | F20: =SUM(F19:F19) -> 20.1 | G20: =SUM(G19:G19) -> 30 | H20: =SUM(H19:H19) -> 0
B22: 🥗 Almoço 13:00h
B23: 🥗 Almoço | C23: Arroz branco cozido | D23: 140 | E23: =IFERROR(VLOOKUP(C23,_Listas!$C$2:$H$80,2,0)*D23/100,0) -> 179.2 | F23: =IFERROR(VLOOKUP(C23,_Listas!$C$2:$H$80,3,0)*D23/100,0) -> 3.5 | G23: =IFERROR(VLOOKUP(C23,_Listas!$C$2:$H$80,4,0)*D23/100,0) -> 39.34 | H23: =IFERROR(VLOOKUP(C23,_Listas!$C$2:$H$80,5,0)*D23/100,0) -> 0.28 | I23: 4 col. sopa
C24: Patê de ricota | D24: 20 | E24: =IFERROR(VLOOKUP(C24,_Listas!$C$2:$H$80,2,0)*D24/100,0) -> 34 | F24: =IFERROR(VLOOKUP(C24,_Listas!$C$2:$H$80,3,0)*D24/100,0) -> 1.6 | G24: =IFERROR(VLOOKUP(C24,_Listas!$C$2:$H$80,4,0)*D24/100,0) -> 1 | H24: =IFERROR(VLOOKUP(C24,_Listas!$C$2:$H$80,5,0)*D24/100,0) -> 2.6 | I24: 1 col. sopa
C25: Requeijão | D25: 40 | E25: =IFERROR(VLOOKUP(C25,_Listas!$C$2:$H$80,2,0)*D25/100,0) -> 96 | F25: =IFERROR(VLOOKUP(C25,_Listas!$C$2:$H$80,3,0)*D25/100,0) -> 2.8 | G25: =IFERROR(VLOOKUP(C25,_Listas!$C$2:$H$80,4,0)*D25/100,0) -> 1.4 | H25: =IFERROR(VLOOKUP(C25,_Listas!$C$2:$H$80,5,0)*D25/100,0) -> 8.8 | I25: 2 col. sopa
C26: Filé de frango grelhado | D26: 170 | E26: =IFERROR(VLOOKUP(C26,_Listas!$C$2:$H$80,2,0)*D26/100,0) -> 277.1 | F26: =IFERROR(VLOOKUP(C26,_Listas!$C$2:$H$80,3,0)*D26/100,0) -> 53.55 | G26: =IFERROR(VLOOKUP(C26,_Listas!$C$2:$H$80,4,0)*D26/100,0) -> 0 | H26: =IFERROR(VLOOKUP(C26,_Listas!$C$2:$H$80,5,0)*D26/100,0) -> 6.29 | I26: 1 filé grande
C27: Laranja pera | D27: 150 | E27: =IFERROR(VLOOKUP(C27,_Listas!$C$2:$H$80,2,0)*D27/100,0) -> 69 | F27: =IFERROR(VLOOKUP(C27,_Listas!$C$2:$H$80,3,0)*D27/100,0) -> 1.35 | G27: =IFERROR(VLOOKUP(C27,_Listas!$C$2:$H$80,4,0)*D27/100,0) -> 17.25 | H27: =IFERROR(VLOOKUP(C27,_Listas!$C$2:$H$80,5,0)*D27/100,0) -> 0.15 | I27: 1 unidade grande
B28: Subtotal 🥗 Almoço | D28: =SUM(D23:D27) -> 520 | E28: =SUM(E23:E27) -> 655.3 | F28: =SUM(F23:F27) -> 62.8 | G28: =SUM(G23:G27) -> 58.99 | H28: =SUM(H23:H27) -> 18.12
B30: 🔄 Opção Almoço (alternativa)
B31: 🔄 Opção Almoço | C31: Purê de batata caseiro | D31: 150 | E31: =IFERROR(VLOOKUP(C31,_Listas!$C$2:$H$80,2,0)*D31/100,0) -> 153 | F31: =IFERROR(VLOOKUP(C31,_Listas!$C$2:$H$80,3,0)*D31/100,0) -> 3.75 | G31: =IFERROR(VLOOKUP(C31,_Listas!$C$2:$H$80,4,0)*D31/100,0) -> 25.5 | H31: =IFERROR(VLOOKUP(C31,_Listas!$C$2:$H$80,5,0)*D31/100,0) -> 4.5 | I31: 1 porção
C32: Moranga cozida | D32: 100 | E32: =IFERROR(VLOOKUP(C32,_Listas!$C$2:$H$80,2,0)*D32/100,0) -> 26 | F32: =IFERROR(VLOOKUP(C32,_Listas!$C$2:$H$80,3,0)*D32/100,0) -> 0.7 | G32: =IFERROR(VLOOKUP(C32,_Listas!$C$2:$H$80,4,0)*D32/100,0) -> 6 | H32: =IFERROR(VLOOKUP(C32,_Listas!$C$2:$H$80,5,0)*D32/100,0) -> 0.1 | I32: 1 porção
C33: Peixe grelhado | D33: 200 | E33: =IFERROR(VLOOKUP(C33,_Listas!$C$2:$H$80,2,0)*D33/100,0) -> 256 | F33: =IFERROR(VLOOKUP(C33,_Listas!$C$2:$H$80,3,0)*D33/100,0) -> 50 | G33: =IFERROR(VLOOKUP(C33,_Listas!$C$2:$H$80,4,0)*D33/100,0) -> 0 | H33: =IFERROR(VLOOKUP(C33,_Listas!$C$2:$H$80,5,0)*D33/100,0) -> 5.6 | I33: 1 filé
C34: Legumes cozidos variados | D34: 120 | E34: =IFERROR(VLOOKUP(C34,_Listas!$C$2:$H$80,2,0)*D34/100,0) -> 42 | F34: =IFERROR(VLOOKUP(C34,_Listas!$C$2:$H$80,3,0)*D34/100,0) -> 2.4 | G34: =IFERROR(VLOOKUP(C34,_Listas!$C$2:$H$80,4,0)*D34/100,0) -> 7.8 | H34: =IFERROR(VLOOKUP(C34,_Listas!$C$2:$H$80,5,0)*D34/100,0) -> 0.36 | I34: 2 porções
C35: Bombom Ouro Branco | D35: 16 | E35: =IFERROR(VLOOKUP(C35,_Listas!$C$2:$H$80,2,0)*D35/100,0) -> 83.2 | F35: =IFERROR(VLOOKUP(C35,_Listas!$C$2:$H$80,3,0)*D35/100,0) -> 0.8 | G35: =IFERROR(VLOOKUP(C35,_Listas!$C$2:$H$80,4,0)*D35/100,0) -> 9.6 | H35: =IFERROR(VLOOKUP(C35,_Listas!$C$2:$H$80,5,0)*D35/100,0) -> 4.48 | I35: 1 unidade
B37: ☕ Café da Tarde 18:00h
B38: ☕ Café da Tarde | C38: Leite de vaca integral | D38: 200 | E38: =IFERROR(VLOOKUP(C38,_Listas!$C$2:$H$80,2,0)*D38/100,0) -> 122 | F38: =IFERROR(VLOOKUP(C38,_Listas!$C$2:$H$80,3,0)*D38/100,0) -> 6.4 | G38: =IFERROR(VLOOKUP(C38,_Listas!$C$2:$H$80,4,0)*D38/100,0) -> 9.4 | H38: =IFERROR(VLOOKUP(C38,_Listas!$C$2:$H$80,5,0)*D38/100,0) -> 6.4 | I38: 1 copo
C39: Banana | D39: 60 | E39: =IFERROR(VLOOKUP(C39,_Listas!$C$2:$H$80,2,0)*D39/100,0) -> 55.2 | F39: =IFERROR(VLOOKUP(C39,_Listas!$C$2:$H$80,3,0)*D39/100,0) -> 0.78 | G39: =IFERROR(VLOOKUP(C39,_Listas!$C$2:$H$80,4,0)*D39/100,0) -> 14.28 | H39: =IFERROR(VLOOKUP(C39,_Listas!$C$2:$H$80,5,0)*D39/100,0) -> 0.06 | I39: ½ unidade
C40: Whey protein | D40: 60 | E40: =IFERROR(VLOOKUP(C40,_Listas!$C$2:$H$80,2,0)*D40/100,0) -> 224.4 | F40: =IFERROR(VLOOKUP(C40,_Listas!$C$2:$H$80,3,0)*D40/100,0) -> 48 | G40: =IFERROR(VLOOKUP(C40,_Listas!$C$2:$H$80,4,0)*D40/100,0) -> 4.8 | H40: =IFERROR(VLOOKUP(C40,_Listas!$C$2:$H$80,5,0)*D40/100,0) -> 2.4 | I40: 2 scoops
B41: Subtotal ☕ Café da Tarde | D41: =SUM(D38:D40) -> 320 | E41: =SUM(E38:E40) -> 401.6 | F41: =SUM(F38:F40) -> 55.18 | G41: =SUM(G38:G40) -> 28.48 | H41: =SUM(H38:H40) -> 8.86
B43: 🌙 Jantar 20:30h
B44: 🌙 Jantar | C44: Coca-Cola Light | D44: 350 | E44: =IFERROR(VLOOKUP(C44,_Listas!$C$2:$H$80,2,0)*D44/100,0) -> 3.5 | F44: =IFERROR(VLOOKUP(C44,_Listas!$C$2:$H$80,3,0)*D44/100,0) -> 0 | G44: =IFERROR(VLOOKUP(C44,_Listas!$C$2:$H$80,4,0)*D44/100,0) -> 1.05 | H44: =IFERROR(VLOOKUP(C44,_Listas!$C$2:$H$80,5,0)*D44/100,0) -> 0 | I44: 1 lata
C45: Pão de hambúrguer | D45: 70 | E45: =IFERROR(VLOOKUP(C45,_Listas!$C$2:$H$80,2,0)*D45/100,0) -> 196 | F45: =IFERROR(VLOOKUP(C45,_Listas!$C$2:$H$80,3,0)*D45/100,0) -> 5.6 | G45: =IFERROR(VLOOKUP(C45,_Listas!$C$2:$H$80,4,0)*D45/100,0) -> 35 | H45: =IFERROR(VLOOKUP(C45,_Listas!$C$2:$H$80,5,0)*D45/100,0) -> 3.5 | I45: 1 unidade
C46: Queijo mussarela | D46: 25 | E46: =IFERROR(VLOOKUP(C46,_Listas!$C$2:$H$80,2,0)*D46/100,0) -> 72.25 | F46: =IFERROR(VLOOKUP(C46,_Listas!$C$2:$H$80,3,0)*D46/100,0) -> 4.5 | G46: =IFERROR(VLOOKUP(C46,_Listas!$C$2:$H$80,4,0)*D46/100,0) -> 0.65 | H46: =IFERROR(VLOOKUP(C46,_Listas!$C$2:$H$80,5,0)*D46/100,0) -> 5.725 | I46: 1 fatia
C47: Requeijão | D47: 20 | E47: =IFERROR(VLOOKUP(C47,_Listas!$C$2:$H$80,2,0)*D47/100,0) -> 48 | F47: =IFERROR(VLOOKUP(C47,_Listas!$C$2:$H$80,3,0)*D47/100,0) -> 1.4 | G47: =IFERROR(VLOOKUP(C47,_Listas!$C$2:$H$80,4,0)*D47/100,0) -> 0.7 | H47: =IFERROR(VLOOKUP(C47,_Listas!$C$2:$H$80,5,0)*D47/100,0) -> 4.4 | I47: 1 col. sopa
C48: Bife contrafilé grelhado | D48: 150 | E48: =IFERROR(VLOOKUP(C48,_Listas!$C$2:$H$80,2,0)*D48/100,0) -> 355.5 | F48: =IFERROR(VLOOKUP(C48,_Listas!$C$2:$H$80,3,0)*D48/100,0) -> 49.2 | G48: =IFERROR(VLOOKUP(C48,_Listas!$C$2:$H$80,4,0)*D48/100,0) -> 0 | H48: =IFERROR(VLOOKUP(C48,_Listas!$C$2:$H$80,5,0)*D48/100,0) -> 17.1 | I48: 1 bife médio
...

Sheet QUA
B2: 🍽️ PLANO ALIMENTAR · Quarta-feira 🔵 · (=Seg e Sex)
B3: ▼ Clique na seta ▼ em cada alimento para trocar · Edite a porção (g) para recalcular as calorias automaticamente
B4: Meta Kcal/dia: | C4: 2000 | D4: Peso (kg): | E4: 70 | F4: Objetivo: | G4: Emagrecimento
B6: Refeição / Horário | C6: Alimento ▼ | D6: Porção (g) | E6: Kcal | F6: Prot. (g) | G6: Carb. (g) | H6: Gord. (g) | I6: Medida caseira
B8: ☕ Café da Manhã 08:00h
B9: ☕ Café da Manhã | C9: Café sem açúcar | D9: 200 | E9: =IFERROR(VLOOKUP(C9,_Listas!$C$2:$H$80,2,0)*D9/100,0) -> 4 | F9: =IFERROR(VLOOKUP(C9,_Listas!$C$2:$H$80,3,0)*D9/100,0) -> 0.6 | G9: =IFERROR(VLOOKUP(C9,_Listas!$C$2:$H$80,4,0)*D9/100,0) -> 0 | H9: =IFERROR(VLOOKUP(C9,_Listas!$C$2:$H$80,5,0)*D9/100,0) -> 0 | I9: 200 ml
C10: Pão francês | D10: 60 | E10: =IFERROR(VLOOKUP(C10,_Listas!$C$2:$H$80,2,0)*D10/100,0) -> 180 | F10: =IFERROR(VLOOKUP(C10,_Listas!$C$2:$H$80,3,0)*D10/100,0) -> 4.8 | G10: =IFERROR(VLOOKUP(C10,_Listas!$C$2:$H$80,4,0)*D10/100,0) -> 35.16 | H10: =IFERROR(VLOOKUP(C10,_Listas!$C$2:$H$80,5,0)*D10/100,0) -> 1.86 | I10: 1 unidade
C11: Requeijão | D11: 15 | E11: =IFERROR(VLOOKUP(C11,_Listas!$C$2:$H$80,2,0)*D11/100,0) -> 36 | F11: =IFERROR(VLOOKUP(C11,_Listas!$C$2:$H$80,3,0)*D11/100,0) -> 1.05 | G11: =IFERROR(VLOOKUP(C11,_Listas!$C$2:$H$80,4,0)*D11/100,0) -> 0.525 | H11: =IFERROR(VLOOKUP(C11,_Listas!$C$2:$H$80,5,0)*D11/100,0) -> 3.3 | I11: 1 col. sopa
C12: Queijo mussarela | D12: 20 | E12: =IFERROR(VLOOKUP(C12,_Listas!$C$2:$H$80,2,0)*D12/100,0) -> 57.8 | F12: =IFERROR(VLOOKUP(C12,_Listas!$C$2:$H$80,3,0)*D12/100,0) -> 3.6 | G12: =IFERROR(VLOOKUP(C12,_Listas!$C$2:$H$80,4,0)*D12/100,0) -> 0.52 | H12: =IFERROR(VLOOKUP(C12,_Listas!$C$2:$H$80,5,0)*D12/100,0) -> 4.58 | I12: 1 fatia
C13: Banana | D13: 70 | E13: =IFERROR(VLOOKUP(C13,_Listas!$C$2:$H$80,2,0)*D13/100,0) -> 64.4 | F13: =IFERROR(VLOOKUP(C13,_Listas!$C$2:$H$80,3,0)*D13/100,0) -> 0.91 | G13: =IFERROR(VLOOKUP(C13,_Listas!$C$2:$H$80,4,0)*D13/100,0) -> 16.66 | H13: =IFERROR(VLOOKUP(C13,_Listas!$C$2:$H$80,5,0)*D13/100,0) -> 0.07 | I13: ½ unidade méd.
C14: Creatina monohidratada | D14: 6 | E14: =IFERROR(VLOOKUP(C14,_Listas!$C$2:$H$80,2,0)*D14/100,0) -> 0 | F14: =IFERROR(VLOOKUP(C14,_Listas!$C$2:$H$80,3,0)*D14/100,0) -> 0 | G14: =IFERROR(VLOOKUP(C14,_Listas!$C$2:$H$80,4,0)*D14/100,0) -> 0 | H14: =IFERROR(VLOOKUP(C14,_Listas!$C$2:$H$80,5,0)*D14/100,0) -> 0 | I14: 2 doses
B15: Subtotal ☕ Café da Manhã | D15: =SUM(D9:D14) -> 371 | E15: =SUM(E9:E14) -> 342.2 | F15: =SUM(F9:F14) -> 10.96 | G15: =SUM(G9:G14) -> 52.865 | H15: =SUM(H9:H14) -> 9.81
B17: 🍌 Lanche 10:00h
B18: 🍌 Lanche | C18: Yopro 15g High Protein | D18: 300 | E18: =IFERROR(VLOOKUP(C18,_Listas!$C$2:$H$80,2,0)*D18/100,0) -> 201 | F18: =IFERROR(VLOOKUP(C18,_Listas!$C$2:$H$80,3,0)*D18/100,0) -> 20.1 | G18: =IFERROR(VLOOKUP(C18,_Listas!$C$2:$H$80,4,0)*D18/100,0) -> 30 | H18: =IFERROR(VLOOKUP(C18,_Listas!$C$2:$H$80,5,0)*D18/100,0) -> 0 | I18: 1 unidade
B19: Subtotal 🍌 Lanche | D19: =SUM(D18:D18) -> 300 | E19: =SUM(E18:E18) -> 201 | F19: =SUM(F18:F18) -> 20.1 | G19: =SUM(G18:G18) -> 30 | H19: =SUM(H18:H18) -> 0
B21: 🥗 Almoço 13:00h
B22: 🥗 Almoço | C22: Batata inglesa assada | D22: 150 | E22: =IFERROR(VLOOKUP(C22,_Listas!$C$2:$H$80,2,0)*D22/100,0) -> 139.5 | F22: =IFERROR(VLOOKUP(C22,_Listas!$C$2:$H$80,3,0)*D22/100,0) -> 3.75 | G22: =IFERROR(VLOOKUP(C22,_Listas!$C$2:$H$80,4,0)*D22/100,0) -> 31.5 | H22: =IFERROR(VLOOKUP(C22,_Listas!$C$2:$H$80,5,0)*D22/100,0) -> 0.15 | I22: 1 unid. média
C23: Feijão preto cozido | D23: 120 | E23: =IFERROR(VLOOKUP(C23,_Listas!$C$2:$H$80,2,0)*D23/100,0) -> 92.4 | F23: =IFERROR(VLOOKUP(C23,_Listas!$C$2:$H$80,3,0)*D23/100,0) -> 5.4 | G23: =IFERROR(VLOOKUP(C23,_Listas!$C$2:$H$80,4,0)*D23/100,0) -> 16.32 | H23: =IFERROR(VLOOKUP(C23,_Listas!$C$2:$H$80,5,0)*D23/100,0) -> 0.6 | I23: 1 concha
C24: Moranga cozida | D24: 100 | E24: =IFERROR(VLOOKUP(C24,_Listas!$C$2:$H$80,2,0)*D24/100,0) -> 26 | F24: =IFERROR(VLOOKUP(C24,_Listas!$C$2:$H$80,3,0)*D24/100,0) -> 0.7 | G24: =IFERROR(VLOOKUP(C24,_Listas!$C$2:$H$80,4,0)*D24/100,0) -> 6 | H24: =IFERROR(VLOOKUP(C24,_Listas!$C$2:$H$80,5,0)*D24/100,0) -> 0.1 | I24: 1 porção
C25: Sobrecoxa de frango grelhada | D25: 150 | E25: =IFERROR(VLOOKUP(C25,_Listas!$C$2:$H$80,2,0)*D25/100,0) -> 322.5 | F25: =IFERROR(VLOOKUP(C25,_Listas!$C$2:$H$80,3,0)*D25/100,0) -> 31.5 | G25: =IFERROR(VLOOKUP(C25,_Listas!$C$2:$H$80,4,0)*D25/100,0) -> 0 | H25: =IFERROR(VLOOKUP(C25,_Listas!$C$2:$H$80,5,0)*D25/100,0) -> 21 | I25: 1 peça s/ osso
C26: Melancia | D26: 150 | E26: =IFERROR(VLOOKUP(C26,_Listas!$C$2:$H$80,2,0)*D26/100,0) -> 49.5 | F26: =IFERROR(VLOOKUP(C26,_Listas!$C$2:$H$80,3,0)*D26/100,0) -> 1.05 | G26: =IFERROR(VLOOKUP(C26,_Listas!$C$2:$H$80,4,0)*D26/100,0) -> 12 | H26: =IFERROR(VLOOKUP(C26,_Listas!$C$2:$H$80,5,0)*D26/100,0) -> 0.3 | I26: 1 fatia
B27: Subtotal 🥗 Almoço | D27: =SUM(D22:D26) -> 670 | E27: =SUM(E22:E26) -> 629.9 | F27: =SUM(F22:F26) -> 42.4 | G27: =SUM(G22:G26) -> 65.82 | H27: =SUM(H22:H26) -> 22.15
B29: ☕ Café da Tarde 18:00h
B30: ☕ Café da Tarde | C30: Café sem açúcar | D30: 200 | E30: =IFERROR(VLOOKUP(C30,_Listas!$C$2:$H$80,2,0)*D30/100,0) -> 4 | F30: =IFERROR(VLOOKUP(C30,_Listas!$C$2:$H$80,3,0)*D30/100,0) -> 0.6 | G30: =IFERROR(VLOOKUP(C30,_Listas!$C$2:$H$80,4,0)*D30/100,0) -> 0 | H30: =IFERROR(VLOOKUP(C30,_Listas!$C$2:$H$80,5,0)*D30/100,0) -> 0 | I30: 200 ml
C31: Pão francês | D31: 60 | E31: =IFERROR(VLOOKUP(C31,_Listas!$C$2:$H$80,2,0)*D31/100,0) -> 180 | F31: =IFERROR(VLOOKUP(C31,_Listas!$C$2:$H$80,3,0)*D31/100,0) -> 4.8 | G31: =IFERROR(VLOOKUP(C31,_Listas!$C$2:$H$80,4,0)*D31/100,0) -> 35.16 | H31: =IFERROR(VLOOKUP(C31,_Listas!$C$2:$H$80,5,0)*D31/100,0) -> 1.86 | I31: 1 unidade
C32: Filé de frango grelhado | D32: 50 | E32: =IFERROR(VLOOKUP(C32,_Listas!$C$2:$H$80,2,0)*D32/100,0) -> 81.5 | F32: =IFERROR(VLOOKUP(C32,_Listas!$C$2:$H$80,3,0)*D32/100,0) -> 15.75 | G32: =IFERROR(VLOOKUP(C32,_Listas!$C$2:$H$80,4,0)*D32/100,0) -> 0 | H32: =IFERROR(VLOOKUP(C32,_Listas!$C$2:$H$80,5,0)*D32/100,0) -> 1.85 | I32: ½ filé pequeno
C33: Melão | D33: 150 | E33: =IFERROR(VLOOKUP(C33,_Listas!$C$2:$H$80,2,0)*D33/100,0) -> 43.5 | F33: =IFERROR(VLOOKUP(C33,_Listas!$C$2:$H$80,3,0)*D33/100,0) -> 1.05 | G33: =IFERROR(VLOOKUP(C33,_Listas!$C$2:$H$80,4,0)*D33/100,0) -> 11.1 | H33: =IFERROR(VLOOKUP(C33,_Listas!$C$2:$H$80,5,0)*D33/100,0) -> 0.15 | I33: 1 fatia
B34: Subtotal ☕ Café da Tarde | D34: =SUM(D30:D33) -> 460 | E34: =SUM(E30:E33) -> 309 | F34: =SUM(F30:F33) -> 22.2 | G34: =SUM(G30:G33) -> 46.26 | H34: =SUM(H30:H33) -> 3.86
B36: 🌙 Jantar 20:30h
B37: 🌙 Jantar | C37: Arroz branco cozido | D37: 140 | E37: =IFERROR(VLOOKUP(C37,_Listas!$C$2:$H$80,2,0)*D37/100,0) -> 179.2 | F37: =IFERROR(VLOOKUP(C37,_Listas!$C$2:$H$80,3,0)*D37/100,0) -> 3.5 | G37: =IFERROR(VLOOKUP(C37,_Listas!$C$2:$H$80,4,0)*D37/100,0) -> 39.34 | H37: =IFERROR(VLOOKUP(C37,_Listas!$C$2:$H$80,5,0)*D37/100,0) -> 0.28 | I37: 4 col. sopa
C38: Feijão preto cozido | D38: 120 | E38: =IFERROR(VLOOKUP(C38,_Listas!$C$2:$H$80,2,0)*D38/100,0) -> 92.4 | F38: =IFERROR(VLOOKUP(C38,_Listas!$C$2:$H$80,3,0)*D38/100,0) -> 5.4 | G38: =IFERROR(VLOOKUP(C38,_Listas!$C$2:$H$80,4,0)*D38/100,0) -> 16.32 | H38: =IFERROR(VLOOKUP(C38,_Listas!$C$2:$H$80,5,0)*D38/100,0) -> 0.6 | I38: 1 concha
C39: Filé de frango grelhado | D39: 140 | E39: =IFERROR(VLOOKUP(C39,_Listas!$C$2:$H$80,2,0)*D39/100,0) -> 228.2 | F39: =IFERROR(VLOOKUP(C39,_Listas!$C$2:$H$80,3,0)*D39/100,0) -> 44.1 | G39: =IFERROR(VLOOKUP(C39,_Listas!$C$2:$H$80,4,0)*D39/100,0) -> 0 | H39: =IFERROR(VLOOKUP(C39,_Listas!$C$2:$H$80,5,0)*D39/100,0) -> 5.18 | I39: 1 filé médio
C40: Melão | D40: 150 | E40: =IFERROR(VLOOKUP(C40,_Listas!$C$2:$H$80,2,0)*D40/100,0) -> 43.5 | F40: =IFERROR(VLOOKUP(C40,_Listas!$C$2:$H$80,3,0)*D40/100,0) -> 1.05 | G40: =IFERROR(VLOOKUP(C40,_Listas!$C$2:$H$80,4,0)*D40/100,0) -> 11.1 | H40: =IFERROR(VLOOKUP(C40,_Listas!$C$2:$H$80,5,0)*D40/100,0) -> 0.15 | I40: 1 fatia
B41: Subtotal 🌙 Jantar | D41: =SUM(D37:D40) -> 550 | E41: =SUM(E37:E40) -> 543.3 | F41: =SUM(F37:F40) -> 54.05 | G41: =SUM(G37:G40) -> 66.76 | H41: =SUM(H37:H40) -> 6.21
B43: 🔄 Opção Jantar (alternativa)
B44: 🔄 Opção Jantar | C44: Suco de laranja natural | D44: 200 | E44: =IFERROR(VLOOKUP(C44,_Listas!$C$2:$H$80,2,0)*D44/100,0) -> 90 | F44: =IFERROR(VLOOKUP(C44,_Listas!$C$2:$H$80,3,0)*D44/100,0) -> 1.4 | G44: =IFERROR(VLOOKUP(C44,_Listas!$C$2:$H$80,4,0)*D44/100,0) -> 21.4 | H44: =IFERROR(VLOOKUP(C44,_Listas!$C$2:$H$80,5,0)*D44/100,0) -> 0.4 | I44: 1 copo
C45: Tapioca de goma | D45: 30 | E45: =IFERROR(VLOOKUP(C45,_Listas!$C$2:$H$80,2,0)*D45/100,0) -> 106.2 | F45: =IFERROR(VLOOKUP(C45,_Listas!$C$2:$H$80,3,0)*D45/100,0) -> 0.03 | G45: =IFERROR(VLOOKUP(C45,_Listas!$C$2:$H$80,4,0)*D45/100,0) -> 26.34 | H45: =IFERROR(VLOOKUP(C45,_Listas!$C$2:$H$80,5,0)*D45/100,0) -> 0.09 | I45: 1 tapioca peq.
C46: Ovo de galinha cozido | D46: 100 | E46: =IFERROR(VLOOKUP(C46,_Listas!$C$2:$H$80,2,0)*D46/100,0) -> 146 | F46: =IFERROR(VLOOKUP(C46,_Listas!$C$2:$H$80,3,0)*D46/100,0) -> 13.3 | G46: =IFERROR(VLOOKUP(C46,_Listas!$C$2:$H$80,4,0)*D46/100,0) -> 0.6 | H46: =IFERROR(VLOOKUP(C46,_Listas!$C$2:$H$80,5,0)*D46/100,0) -> 10 | I46: 2 unidades
C47: Queijo mussarela | D47: 20 | E47: =IFERROR(VLOOKUP(C47,_Listas!$C$2:$H$80,2,0)*D47/100,0) -> 57.8 | F47: =IFERROR(VLOOKUP(C47,_Listas!$C$2:$H$80,3,0)*D47/100,0) -> 3.6 | G47: =IFERROR(VLOOKUP(C47,_Listas!$C$2:$H$80,4,0)*D47/100,0) -> 0.52 | H47: =IFERROR(VLOOKUP(C47,_Listas!$C$2:$H$80,5,0)*D47/100,0) -> 4.58 | I47: 1 fatia
C48: Filé de frango grelhado | D48: 80 | E48: =IFERROR(VLOOKUP(C48,_Listas!$C$2:$H$80,2,0)*D48/100,0) -> 130.4 | F48: =IFERROR(VLOOKUP(C48,_Listas!$C$2:$H$80,3,0)*D48/100,0) -> 25.2 | G48: =IFERROR(VLOOKUP(C48,_Listas!$C$2:$H$80,4,0)*D48/100,0) -> 0 | H48: =IFERROR(VLOOKUP(C48,_Listas!$C$2:$H$80,5,0)*D48/100,0) -> 2.96 | I48: 1 filé pequeno
...

Sheet QUI
B2: 🍽️ PLANO ALIMENTAR · Quinta-feira 🟢 · (=Ter e Sab)
B3: ▼ Clique na seta ▼ em cada alimento para trocar · Edite a porção (g) para recalcular as calorias automaticamente
B4: Meta Kcal/dia: | C4: 2000 | D4: Peso (kg): | E4: 70 | F4: Objetivo: | G4: Emagrecimento
B6: Refeição / Horário | C6: Alimento ▼ | D6: Porção (g) | E6: Kcal | F6: Prot. (g) | G6: Carb. (g) | H6: Gord. (g) | I6: Medida caseira
B8: ☕ Café da Manhã 08:00h
B9: ☕ Café da Manhã | C9: Café sem açúcar | D9: 200 | E9: =IFERROR(VLOOKUP(C9,_Listas!$C$2:$H$80,2,0)*D9/100,0) -> 4 | F9: =IFERROR(VLOOKUP(C9,_Listas!$C$2:$H$80,3,0)*D9/100,0) -> 0.6 | G9: =IFERROR(VLOOKUP(C9,_Listas!$C$2:$H$80,4,0)*D9/100,0) -> 0 | H9: =IFERROR(VLOOKUP(C9,_Listas!$C$2:$H$80,5,0)*D9/100,0) -> 0 | I9: 200 ml
C10: Pão francês | D10: 60 | E10: =IFERROR(VLOOKUP(C10,_Listas!$C$2:$H$80,2,0)*D10/100,0) -> 180 | F10: =IFERROR(VLOOKUP(C10,_Listas!$C$2:$H$80,3,0)*D10/100,0) -> 4.8 | G10: =IFERROR(VLOOKUP(C10,_Listas!$C$2:$H$80,4,0)*D10/100,0) -> 35.16 | H10: =IFERROR(VLOOKUP(C10,_Listas!$C$2:$H$80,5,0)*D10/100,0) -> 1.86 | I10: 1 unidade
C11: Requeijão | D11: 15 | E11: =IFERROR(VLOOKUP(C11,_Listas!$C$2:$H$80,2,0)*D11/100,0) -> 36 | F11: =IFERROR(VLOOKUP(C11,_Listas!$C$2:$H$80,3,0)*D11/100,0) -> 1.05 | G11: =IFERROR(VLOOKUP(C11,_Listas!$C$2:$H$80,4,0)*D11/100,0) -> 0.525 | H11: =IFERROR(VLOOKUP(C11,_Listas!$C$2:$H$80,5,0)*D11/100,0) -> 3.3 | I11: 1 col. sopa
C12: Queijo mussarela | D12: 20 | E12: =IFERROR(VLOOKUP(C12,_Listas!$C$2:$H$80,2,0)*D12/100,0) -> 57.8 | F12: =IFERROR(VLOOKUP(C12,_Listas!$C$2:$H$80,3,0)*D12/100,0) -> 3.6 | G12: =IFERROR(VLOOKUP(C12,_Listas!$C$2:$H$80,4,0)*D12/100,0) -> 0.52 | H12: =IFERROR(VLOOKUP(C12,_Listas!$C$2:$H$80,5,0)*D12/100,0) -> 4.58 | I12: 1 fatia
C13: Peito de peru fatiado | D13: 15 | E13: =IFERROR(VLOOKUP(C13,_Listas!$C$2:$H$80,2,0)*D13/100,0) -> 16.35 | F13: =IFERROR(VLOOKUP(C13,_Listas!$C$2:$H$80,3,0)*D13/100,0) -> 2.61 | G13: =IFERROR(VLOOKUP(C13,_Listas!$C$2:$H$80,4,0)*D13/100,0) -> 0.285 | H13: =IFERROR(VLOOKUP(C13,_Listas!$C$2:$H$80,5,0)*D13/100,0) -> 0.54 | I13: 1 fatia
C14: Maçã com casca | D14: 120 | E14: =IFERROR(VLOOKUP(C14,_Listas!$C$2:$H$80,2,0)*D14/100,0) -> 67.2 | F14: =IFERROR(VLOOKUP(C14,_Listas!$C$2:$H$80,3,0)*D14/100,0) -> 0.36 | G14: =IFERROR(VLOOKUP(C14,_Listas!$C$2:$H$80,4,0)*D14/100,0) -> 17.88 | H14: =IFERROR(VLOOKUP(C14,_Listas!$C$2:$H$80,5,0)*D14/100,0) -> 0.12 | I14: 1 unid. média
C15: Creatina monohidratada | D15: 6 | E15: =IFERROR(VLOOKUP(C15,_Listas!$C$2:$H$80,2,0)*D15/100,0) -> 0 | F15: =IFERROR(VLOOKUP(C15,_Listas!$C$2:$H$80,3,0)*D15/100,0) -> 0 | G15: =IFERROR(VLOOKUP(C15,_Listas!$C$2:$H$80,4,0)*D15/100,0) -> 0 | H15: =IFERROR(VLOOKUP(C15,_Listas!$C$2:$H$80,5,0)*D15/100,0) -> 0 | I15: 2 doses
B16: Subtotal ☕ Café da Manhã | D16: =SUM(D9:D15) -> 436 | E16: =SUM(E9:E15) -> 361.35 | F16: =SUM(F9:F15) -> 13.02 | G16: =SUM(G9:G15) -> 54.37 | H16: =SUM(H9:H15) -> 10.4
B18: 🍌 Lanche 10:00h
B19: 🍌 Lanche | C19: Yopro 15g High Protein | D19: 300 | E19: =IFERROR(VLOOKUP(C19,_Listas!$C$2:$H$80,2,0)*D19/100,0) -> 201 | F19: =IFERROR(VLOOKUP(C19,_Listas!$C$2:$H$80,3,0)*D19/100,0) -> 20.1 | G19: =IFERROR(VLOOKUP(C19,_Listas!$C$2:$H$80,4,0)*D19/100,0) -> 30 | H19: =IFERROR(VLOOKUP(C19,_Listas!$C$2:$H$80,5,0)*D19/100,0) -> 0 | I19: 1 unidade
B20: Subtotal 🍌 Lanche | D20: =SUM(D19:D19) -> 300 | E20: =SUM(E19:E19) -> 201 | F20: =SUM(F19:F19) -> 20.1 | G20: =SUM(G19:G19) -> 30 | H20: =SUM(H19:H19) -> 0
B22: 🥗 Almoço 13:00h
B23: 🥗 Almoço | C23: Arroz branco cozido | D23: 140 | E23: =IFERROR(VLOOKUP(C23,_Listas!$C$2:$H$80,2,0)*D23/100,0) -> 179.2 | F23: =IFERROR(VLOOKUP(C23,_Listas!$C$2:$H$80,3,0)*D23/100,0) -> 3.5 | G23: =IFERROR(VLOOKUP(C23,_Listas!$C$2:$H$80,4,0)*D23/100,0) -> 39.34 | H23: =IFERROR(VLOOKUP(C23,_Listas!$C$2:$H$80,5,0)*D23/100,0) -> 0.28 | I23: 4 col. sopa
C24: Patê de ricota | D24: 20 | E24: =IFERROR(VLOOKUP(C24,_Listas!$C$2:$H$80,2,0)*D24/100,0) -> 34 | F24: =IFERROR(VLOOKUP(C24,_Listas!$C$2:$H$80,3,0)*D24/100,0) -> 1.6 | G24: =IFERROR(VLOOKUP(C24,_Listas!$C$2:$H$80,4,0)*D24/100,0) -> 1 | H24: =IFERROR(VLOOKUP(C24,_Listas!$C$2:$H$80,5,0)*D24/100,0) -> 2.6 | I24: 1 col. sopa
C25: Requeijão | D25: 40 | E25: =IFERROR(VLOOKUP(C25,_Listas!$C$2:$H$80,2,0)*D25/100,0) -> 96 | F25: =IFERROR(VLOOKUP(C25,_Listas!$C$2:$H$80,3,0)*D25/100,0) -> 2.8 | G25: =IFERROR(VLOOKUP(C25,_Listas!$C$2:$H$80,4,0)*D25/100,0) -> 1.4 | H25: =IFERROR(VLOOKUP(C25,_Listas!$C$2:$H$80,5,0)*D25/100,0) -> 8.8 | I25: 2 col. sopa
C26: Filé de frango grelhado | D26: 170 | E26: =IFERROR(VLOOKUP(C26,_Listas!$C$2:$H$80,2,0)*D26/100,0) -> 277.1 | F26: =IFERROR(VLOOKUP(C26,_Listas!$C$2:$H$80,3,0)*D26/100,0) -> 53.55 | G26: =IFERROR(VLOOKUP(C26,_Listas!$C$2:$H$80,4,0)*D26/100,0) -> 0 | H26: =IFERROR(VLOOKUP(C26,_Listas!$C$2:$H$80,5,0)*D26/100,0) -> 6.29 | I26: 1 filé grande
C27: Laranja pera | D27: 150 | E27: =IFERROR(VLOOKUP(C27,_Listas!$C$2:$H$80,2,0)*D27/100,0) -> 69 | F27: =IFERROR(VLOOKUP(C27,_Listas!$C$2:$H$80,3,0)*D27/100,0) -> 1.35 | G27: =IFERROR(VLOOKUP(C27,_Listas!$C$2:$H$80,4,0)*D27/100,0) -> 17.25 | H27: =IFERROR(VLOOKUP(C27,_Listas!$C$2:$H$80,5,0)*D27/100,0) -> 0.15 | I27: 1 unidade grande
B28: Subtotal 🥗 Almoço | D28: =SUM(D23:D27) -> 520 | E28: =SUM(E23:E27) -> 655.3 | F28: =SUM(F23:F27) -> 62.8 | G28: =SUM(G23:G27) -> 58.99 | H28: =SUM(H23:H27) -> 18.12
B30: 🔄 Opção Almoço (alternativa)
B31: 🔄 Opção Almoço | C31: Purê de batata caseiro | D31: 150 | E31: =IFERROR(VLOOKUP(C31,_Listas!$C$2:$H$80,2,0)*D31/100,0) -> 153 | F31: =IFERROR(VLOOKUP(C31,_Listas!$C$2:$H$80,3,0)*D31/100,0) -> 3.75 | G31: =IFERROR(VLOOKUP(C31,_Listas!$C$2:$H$80,4,0)*D31/100,0) -> 25.5 | H31: =IFERROR(VLOOKUP(C31,_Listas!$C$2:$H$80,5,0)*D31/100,0) -> 4.5 | I31: 1 porção
C32: Moranga cozida | D32: 100 | E32: =IFERROR(VLOOKUP(C32,_Listas!$C$2:$H$80,2,0)*D32/100,0) -> 26 | F32: =IFERROR(VLOOKUP(C32,_Listas!$C$2:$H$80,3,0)*D32/100,0) -> 0.7 | G32: =IFERROR(VLOOKUP(C32,_Listas!$C$2:$H$80,4,0)*D32/100,0) -> 6 | H32: =IFERROR(VLOOKUP(C32,_Listas!$C$2:$H$80,5,0)*D32/100,0) -> 0.1 | I32: 1 porção
C33: Peixe grelhado | D33: 200 | E33: =IFERROR(VLOOKUP(C33,_Listas!$C$2:$H$80,2,0)*D33/100,0) -> 256 | F33: =IFERROR(VLOOKUP(C33,_Listas!$C$2:$H$80,3,0)*D33/100,0) -> 50 | G33: =IFERROR(VLOOKUP(C33,_Listas!$C$2:$H$80,4,0)*D33/100,0) -> 0 | H33: =IFERROR(VLOOKUP(C33,_Listas!$C$2:$H$80,5,0)*D33/100,0) -> 5.6 | I33: 1 filé
C34: Legumes cozidos variados | D34: 120 | E34: =IFERROR(VLOOKUP(C34,_Listas!$C$2:$H$80,2,0)*D34/100,0) -> 42 | F34: =IFERROR(VLOOKUP(C34,_Listas!$C$2:$H$80,3,0)*D34/100,0) -> 2.4 | G34: =IFERROR(VLOOKUP(C34,_Listas!$C$2:$H$80,4,0)*D34/100,0) -> 7.8 | H34: =IFERROR(VLOOKUP(C34,_Listas!$C$2:$H$80,5,0)*D34/100,0) -> 0.36 | I34: 2 porções
C35: Bombom Ouro Branco | D35: 16 | E35: =IFERROR(VLOOKUP(C35,_Listas!$C$2:$H$80,2,0)*D35/100,0) -> 83.2 | F35: =IFERROR(VLOOKUP(C35,_Listas!$C$2:$H$80,3,0)*D35/100,0) -> 0.8 | G35: =IFERROR(VLOOKUP(C35,_Listas!$C$2:$H$80,4,0)*D35/100,0) -> 9.6 | H35: =IFERROR(VLOOKUP(C35,_Listas!$C$2:$H$80,5,0)*D35/100,0) -> 4.48 | I35: 1 unidade
B37: ☕ Café da Tarde 18:00h
B38: ☕ Café da Tarde | C38: Leite de vaca integral | D38: 200 | E38: =IFERROR(VLOOKUP(C38,_Listas!$C$2:$H$80,2,0)*D38/100,0) -> 122 | F38: =IFERROR(VLOOKUP(C38,_Listas!$C$2:$H$80,3,0)*D38/100,0) -> 6.4 | G38: =IFERROR(VLOOKUP(C38,_Listas!$C$2:$H$80,4,0)*D38/100,0) -> 9.4 | H38: =IFERROR(VLOOKUP(C38,_Listas!$C$2:$H$80,5,0)*D38/100,0) -> 6.4 | I38: 1 copo
C39: Banana | D39: 60 | E39: =IFERROR(VLOOKUP(C39,_Listas!$C$2:$H$80,2,0)*D39/100,0) -> 55.2 | F39: =IFERROR(VLOOKUP(C39,_Listas!$C$2:$H$80,3,0)*D39/100,0) -> 0.78 | G39: =IFERROR(VLOOKUP(C39,_Listas!$C$2:$H$80,4,0)*D39/100,0) -> 14.28 | H39: =IFERROR(VLOOKUP(C39,_Listas!$C$2:$H$80,5,0)*D39/100,0) -> 0.06 | I39: ½ unidade
C40: Whey protein | D40: 60 | E40: =IFERROR(VLOOKUP(C40,_Listas!$C$2:$H$80,2,0)*D40/100,0) -> 224.4 | F40: =IFERROR(VLOOKUP(C40,_Listas!$C$2:$H$80,3,0)*D40/100,0) -> 48 | G40: =IFERROR(VLOOKUP(C40,_Listas!$C$2:$H$80,4,0)*D40/100,0) -> 4.8 | H40: =IFERROR(VLOOKUP(C40,_Listas!$C$2:$H$80,5,0)*D40/100,0) -> 2.4 | I40: 2 scoops
B41: Subtotal ☕ Café da Tarde | D41: =SUM(D38:D40) -> 320 | E41: =SUM(E38:E40) -> 401.6 | F41: =SUM(F38:F40) -> 55.18 | G41: =SUM(G38:G40) -> 28.48 | H41: =SUM(H38:H40) -> 8.86
B43: 🌙 Jantar 20:30h
B44: 🌙 Jantar | C44: Coca-Cola Light | D44: 350 | E44: =IFERROR(VLOOKUP(C44,_Listas!$C$2:$H$80,2,0)*D44/100,0) -> 3.5 | F44: =IFERROR(VLOOKUP(C44,_Listas!$C$2:$H$80,3,0)*D44/100,0) -> 0 | G44: =IFERROR(VLOOKUP(C44,_Listas!$C$2:$H$80,4,0)*D44/100,0) -> 1.05 | H44: =IFERROR(VLOOKUP(C44,_Listas!$C$2:$H$80,5,0)*D44/100,0) -> 0 | I44: 1 lata
C45: Pão de hambúrguer | D45: 70 | E45: =IFERROR(VLOOKUP(C45,_Listas!$C$2:$H$80,2,0)*D45/100,0) -> 196 | F45: =IFERROR(VLOOKUP(C45,_Listas!$C$2:$H$80,3,0)*D45/100,0) -> 5.6 | G45: =IFERROR(VLOOKUP(C45,_Listas!$C$2:$H$80,4,0)*D45/100,0) -> 35 | H45: =IFERROR(VLOOKUP(C45,_Listas!$C$2:$H$80,5,0)*D45/100,0) -> 3.5 | I45: 1 unidade
C46: Queijo mussarela | D46: 25 | E46: =IFERROR(VLOOKUP(C46,_Listas!$C$2:$H$80,2,0)*D46/100,0) -> 72.25 | F46: =IFERROR(VLOOKUP(C46,_Listas!$C$2:$H$80,3,0)*D46/100,0) -> 4.5 | G46: =IFERROR(VLOOKUP(C46,_Listas!$C$2:$H$80,4,0)*D46/100,0) -> 0.65 | H46: =IFERROR(VLOOKUP(C46,_Listas!$C$2:$H$80,5,0)*D46/100,0) -> 5.725 | I46: 1 fatia
C47: Requeijão | D47: 20 | E47: =IFERROR(VLOOKUP(C47,_Listas!$C$2:$H$80,2,0)*D47/100,0) -> 48 | F47: =IFERROR(VLOOKUP(C47,_Listas!$C$2:$H$80,3,0)*D47/100,0) -> 1.4 | G47: =IFERROR(VLOOKUP(C47,_Listas!$C$2:$H$80,4,0)*D47/100,0) -> 0.7 | H47: =IFERROR(VLOOKUP(C47,_Listas!$C$2:$H$80,5,0)*D47/100,0) -> 4.4 | I47: 1 col. sopa
C48: Bife contrafilé grelhado | D48: 150 | E48: =IFERROR(VLOOKUP(C48,_Listas!$C$2:$H$80,2,0)*D48/100,0) -> 355.5 | F48: =IFERROR(VLOOKUP(C48,_Listas!$C$2:$H$80,3,0)*D48/100,0) -> 49.2 | G48: =IFERROR(VLOOKUP(C48,_Listas!$C$2:$H$80,4,0)*D48/100,0) -> 0 | H48: =IFERROR(VLOOKUP(C48,_Listas!$C$2:$H$80,5,0)*D48/100,0) -> 17.1 | I48: 1 bife médio
...

Sheet SEX
B2: 🍽️ PLANO ALIMENTAR · Sexta-feira 🔵 · (=Seg e Qua)
B3: ▼ Clique na seta ▼ em cada alimento para trocar · Edite a porção (g) para recalcular as calorias automaticamente
B4: Meta Kcal/dia: | C4: 2000 | D4: Peso (kg): | E4: 70 | F4: Objetivo: | G4: Emagrecimento
B6: Refeição / Horário | C6: Alimento ▼ | D6: Porção (g) | E6: Kcal | F6: Prot. (g) | G6: Carb. (g) | H6: Gord. (g) | I6: Medida caseira
B8: ☕ Café da Manhã 08:00h
B9: ☕ Café da Manhã | C9: Café sem açúcar | D9: 200 | E9: =IFERROR(VLOOKUP(C9,_Listas!$C$2:$H$80,2,0)*D9/100,0) -> 4 | F9: =IFERROR(VLOOKUP(C9,_Listas!$C$2:$H$80,3,0)*D9/100,0) -> 0.6 | G9: =IFERROR(VLOOKUP(C9,_Listas!$C$2:$H$80,4,0)*D9/100,0) -> 0 | H9: =IFERROR(VLOOKUP(C9,_Listas!$C$2:$H$80,5,0)*D9/100,0) -> 0 | I9: 200 ml
C10: Pão francês | D10: 60 | E10: =IFERROR(VLOOKUP(C10,_Listas!$C$2:$H$80,2,0)*D10/100,0) -> 180 | F10: =IFERROR(VLOOKUP(C10,_Listas!$C$2:$H$80,3,0)*D10/100,0) -> 4.8 | G10: =IFERROR(VLOOKUP(C10,_Listas!$C$2:$H$80,4,0)*D10/100,0) -> 35.16 | H10: =IFERROR(VLOOKUP(C10,_Listas!$C$2:$H$80,5,0)*D10/100,0) -> 1.86 | I10: 1 unidade
C11: Requeijão | D11: 15 | E11: =IFERROR(VLOOKUP(C11,_Listas!$C$2:$H$80,2,0)*D11/100,0) -> 36 | F11: =IFERROR(VLOOKUP(C11,_Listas!$C$2:$H$80,3,0)*D11/100,0) -> 1.05 | G11: =IFERROR(VLOOKUP(C11,_Listas!$C$2:$H$80,4,0)*D11/100,0) -> 0.525 | H11: =IFERROR(VLOOKUP(C11,_Listas!$C$2:$H$80,5,0)*D11/100,0) -> 3.3 | I11: 1 col. sopa
C12: Queijo mussarela | D12: 20 | E12: =IFERROR(VLOOKUP(C12,_Listas!$C$2:$H$80,2,0)*D12/100,0) -> 57.8 | F12: =IFERROR(VLOOKUP(C12,_Listas!$C$2:$H$80,3,0)*D12/100,0) -> 3.6 | G12: =IFERROR(VLOOKUP(C12,_Listas!$C$2:$H$80,4,0)*D12/100,0) -> 0.52 | H12: =IFERROR(VLOOKUP(C12,_Listas!$C$2:$H$80,5,0)*D12/100,0) -> 4.58 | I12: 1 fatia
C13: Banana | D13: 70 | E13: =IFERROR(VLOOKUP(C13,_Listas!$C$2:$H$80,2,0)*D13/100,0) -> 64.4 | F13: =IFERROR(VLOOKUP(C13,_Listas!$C$2:$H$80,3,0)*D13/100,0) -> 0.91 | G13: =IFERROR(VLOOKUP(C13,_Listas!$C$2:$H$80,4,0)*D13/100,0) -> 16.66 | H13: =IFERROR(VLOOKUP(C13,_Listas!$C$2:$H$80,5,0)*D13/100,0) -> 0.07 | I13: ½ unidade méd.
C14: Creatina monohidratada | D14: 6 | E14: =IFERROR(VLOOKUP(C14,_Listas!$C$2:$H$80,2,0)*D14/100,0) -> 0 | F14: =IFERROR(VLOOKUP(C14,_Listas!$C$2:$H$80,3,0)*D14/100,0) -> 0 | G14: =IFERROR(VLOOKUP(C14,_Listas!$C$2:$H$80,4,0)*D14/100,0) -> 0 | H14: =IFERROR(VLOOKUP(C14,_Listas!$C$2:$H$80,5,0)*D14/100,0) -> 0 | I14: 2 doses
B15: Subtotal ☕ Café da Manhã | D15: =SUM(D9:D14) -> 371 | E15: =SUM(E9:E14) -> 342.2 | F15: =SUM(F9:F14) -> 10.96 | G15: =SUM(G9:G14) -> 52.865 | H15: =SUM(H9:H14) -> 9.81
B17: 🍌 Lanche 10:00h
B18: 🍌 Lanche | C18: Yopro 15g High Protein | D18: 300 | E18: =IFERROR(VLOOKUP(C18,_Listas!$C$2:$H$80,2,0)*D18/100,0) -> 201 | F18: =IFERROR(VLOOKUP(C18,_Listas!$C$2:$H$80,3,0)*D18/100,0) -> 20.1 | G18: =IFERROR(VLOOKUP(C18,_Listas!$C$2:$H$80,4,0)*D18/100,0) -> 30 | H18: =IFERROR(VLOOKUP(C18,_Listas!$C$2:$H$80,5,0)*D18/100,0) -> 0 | I18: 1 unidade
B19: Subtotal 🍌 Lanche | D19: =SUM(D18:D18) -> 300 | E19: =SUM(E18:E18) -> 201 | F19: =SUM(F18:F18) -> 20.1 | G19: =SUM(G18:G18) -> 30 | H19: =SUM(H18:H18) -> 0
B21: 🥗 Almoço 13:00h
B22: 🥗 Almoço | C22: Batata inglesa assada | D22: 150 | E22: =IFERROR(VLOOKUP(C22,_Listas!$C$2:$H$80,2,0)*D22/100,0) -> 139.5 | F22: =IFERROR(VLOOKUP(C22,_Listas!$C$2:$H$80,3,0)*D22/100,0) -> 3.75 | G22: =IFERROR(VLOOKUP(C22,_Listas!$C$2:$H$80,4,0)*D22/100,0) -> 31.5 | H22: =IFERROR(VLOOKUP(C22,_Listas!$C$2:$H$80,5,0)*D22/100,0) -> 0.15 | I22: 1 unid. média
C23: Feijão preto cozido | D23: 120 | E23: =IFERROR(VLOOKUP(C23,_Listas!$C$2:$H$80,2,0)*D23/100,0) -> 92.4 | F23: =IFERROR(VLOOKUP(C23,_Listas!$C$2:$H$80,3,0)*D23/100,0) -> 5.4 | G23: =IFERROR(VLOOKUP(C23,_Listas!$C$2:$H$80,4,0)*D23/100,0) -> 16.32 | H23: =IFERROR(VLOOKUP(C23,_Listas!$C$2:$H$80,5,0)*D23/100,0) -> 0.6 | I23: 1 concha
C24: Moranga cozida | D24: 100 | E24: =IFERROR(VLOOKUP(C24,_Listas!$C$2:$H$80,2,0)*D24/100,0) -> 26 | F24: =IFERROR(VLOOKUP(C24,_Listas!$C$2:$H$80,3,0)*D24/100,0) -> 0.7 | G24: =IFERROR(VLOOKUP(C24,_Listas!$C$2:$H$80,4,0)*D24/100,0) -> 6 | H24: =IFERROR(VLOOKUP(C24,_Listas!$C$2:$H$80,5,0)*D24/100,0) -> 0.1 | I24: 1 porção
C25: Sobrecoxa de frango grelhada | D25: 150 | E25: =IFERROR(VLOOKUP(C25,_Listas!$C$2:$H$80,2,0)*D25/100,0) -> 322.5 | F25: =IFERROR(VLOOKUP(C25,_Listas!$C$2:$H$80,3,0)*D25/100,0) -> 31.5 | G25: =IFERROR(VLOOKUP(C25,_Listas!$C$2:$H$80,4,0)*D25/100,0) -> 0 | H25: =IFERROR(VLOOKUP(C25,_Listas!$C$2:$H$80,5,0)*D25/100,0) -> 21 | I25: 1 peça s/ osso
C26: Melancia | D26: 150 | E26: =IFERROR(VLOOKUP(C26,_Listas!$C$2:$H$80,2,0)*D26/100,0) -> 49.5 | F26: =IFERROR(VLOOKUP(C26,_Listas!$C$2:$H$80,3,0)*D26/100,0) -> 1.05 | G26: =IFERROR(VLOOKUP(C26,_Listas!$C$2:$H$80,4,0)*D26/100,0) -> 12 | H26: =IFERROR(VLOOKUP(C26,_Listas!$C$2:$H$80,5,0)*D26/100,0) -> 0.3 | I26: 1 fatia
B27: Subtotal 🥗 Almoço | D27: =SUM(D22:D26) -> 670 | E27: =SUM(E22:E26) -> 629.9 | F27: =SUM(F22:F26) -> 42.4 | G27: =SUM(G22:G26) -> 65.82 | H27: =SUM(H22:H26) -> 22.15
B29: ☕ Café da Tarde 18:00h
B30: ☕ Café da Tarde | C30: Café sem açúcar | D30: 200 | E30: =IFERROR(VLOOKUP(C30,_Listas!$C$2:$H$80,2,0)*D30/100,0) -> 4 | F30: =IFERROR(VLOOKUP(C30,_Listas!$C$2:$H$80,3,0)*D30/100,0) -> 0.6 | G30: =IFERROR(VLOOKUP(C30,_Listas!$C$2:$H$80,4,0)*D30/100,0) -> 0 | H30: =IFERROR(VLOOKUP(C30,_Listas!$C$2:$H$80,5,0)*D30/100,0) -> 0 | I30: 200 ml
C31: Pão francês | D31: 60 | E31: =IFERROR(VLOOKUP(C31,_Listas!$C$2:$H$80,2,0)*D31/100,0) -> 180 | F31: =IFERROR(VLOOKUP(C31,_Listas!$C$2:$H$80,3,0)*D31/100,0) -> 4.8 | G31: =IFERROR(VLOOKUP(C31,_Listas!$C$2:$H$80,4,0)*D31/100,0) -> 35.16 | H31: =IFERROR(VLOOKUP(C31,_Listas!$C$2:$H$80,5,0)*D31/100,0) -> 1.86 | I31: 1 unidade
C32: Filé de frango grelhado | D32: 50 | E32: =IFERROR(VLOOKUP(C32,_Listas!$C$2:$H$80,2,0)*D32/100,0) -> 81.5 | F32: =IFERROR(VLOOKUP(C32,_Listas!$C$2:$H$80,3,0)*D32/100,0) -> 15.75 | G32: =IFERROR(VLOOKUP(C32,_Listas!$C$2:$H$80,4,0)*D32/100,0) -> 0 | H32: =IFERROR(VLOOKUP(C32,_Listas!$C$2:$H$80,5,0)*D32/100,0) -> 1.85 | I32: ½ filé pequeno
C33: Melão | D33: 150 | E33: =IFERROR(VLOOKUP(C33,_Listas!$C$2:$H$80,2,0)*D33/100,0) -> 43.5 | F33: =IFERROR(VLOOKUP(C33,_Listas!$C$2:$H$80,3,0)*D33/100,0) -> 1.05 | G33: =IFERROR(VLOOKUP(C33,_Listas!$C$2:$H$80,4,0)*D33/100,0) -> 11.1 | H33: =IFERROR(VLOOKUP(C33,_Listas!$C$2:$H$80,5,0)*D33/100,0) -> 0.15 | I33: 1 fatia
B34: Subtotal ☕ Café da Tarde | D34: =SUM(D30:D33) -> 460 | E34: =SUM(E30:E33) -> 309 | F34: =SUM(F30:F33) -> 22.2 | G34: =SUM(G30:G33) -> 46.26 | H34: =SUM(H30:H33) -> 3.86
B36: 🌙 Jantar 20:30h
B37: 🌙 Jantar | C37: Arroz branco cozido | D37: 140 | E37: =IFERROR(VLOOKUP(C37,_Listas!$C$2:$H$80,2,0)*D37/100,0) -> 179.2 | F37: =IFERROR(VLOOKUP(C37,_Listas!$C$2:$H$80,3,0)*D37/100,0) -> 3.5 | G37: =IFERROR(VLOOKUP(C37,_Listas!$C$2:$H$80,4,0)*D37/100,0) -> 39.34 | H37: =IFERROR(VLOOKUP(C37,_Listas!$C$2:$H$80,5,0)*D37/100,0) -> 0.28 | I37: 4 col. sopa
C38: Feijão preto cozido | D38: 120 | E38: =IFERROR(VLOOKUP(C38,_Listas!$C$2:$H$80,2,0)*D38/100,0) -> 92.4 | F38: =IFERROR(VLOOKUP(C38,_Listas!$C$2:$H$80,3,0)*D38/100,0) -> 5.4 | G38: =IFERROR(VLOOKUP(C38,_Listas!$C$2:$H$80,4,0)*D38/100,0) -> 16.32 | H38: =IFERROR(VLOOKUP(C38,_Listas!$C$2:$H$80,5,0)*D38/100,0) -> 0.6 | I38: 1 concha
C39: Filé de frango grelhado | D39: 140 | E39: =IFERROR(VLOOKUP(C39,_Listas!$C$2:$H$80,2,0)*D39/100,0) -> 228.2 | F39: =IFERROR(VLOOKUP(C39,_Listas!$C$2:$H$80,3,0)*D39/100,0) -> 44.1 | G39: =IFERROR(VLOOKUP(C39,_Listas!$C$2:$H$80,4,0)*D39/100,0) -> 0 | H39: =IFERROR(VLOOKUP(C39,_Listas!$C$2:$H$80,5,0)*D39/100,0) -> 5.18 | I39: 1 filé médio
C40: Melão | D40: 150 | E40: =IFERROR(VLOOKUP(C40,_Listas!$C$2:$H$80,2,0)*D40/100,0) -> 43.5 | F40: =IFERROR(VLOOKUP(C40,_Listas!$C$2:$H$80,3,0)*D40/100,0) -> 1.05 | G40: =IFERROR(VLOOKUP(C40,_Listas!$C$2:$H$80,4,0)*D40/100,0) -> 11.1 | H40: =IFERROR(VLOOKUP(C40,_Listas!$C$2:$H$80,5,0)*D40/100,0) -> 0.15 | I40: 1 fatia
B41: Subtotal 🌙 Jantar | D41: =SUM(D37:D40) -> 550 | E41: =SUM(E37:E40) -> 543.3 | F41: =SUM(F37:F40) -> 54.05 | G41: =SUM(G37:G40) -> 66.76 | H41: =SUM(H37:H40) -> 6.21
B43: 🔄 Opção Jantar (alternativa)
B44: 🔄 Opção Jantar | C44: Suco de laranja natural | D44: 200 | E44: =IFERROR(VLOOKUP(C44,_Listas!$C$2:$H$80,2,0)*D44/100,0) -> 90 | F44: =IFERROR(VLOOKUP(C44,_Listas!$C$2:$H$80,3,0)*D44/100,0) -> 1.4 | G44: =IFERROR(VLOOKUP(C44,_Listas!$C$2:$H$80,4,0)*D44/100,0) -> 21.4 | H44: =IFERROR(VLOOKUP(C44,_Listas!$C$2:$H$80,5,0)*D44/100,0) -> 0.4 | I44: 1 copo
C45: Tapioca de goma | D45: 30 | E45: =IFERROR(VLOOKUP(C45,_Listas!$C$2:$H$80,2,0)*D45/100,0) -> 106.2 | F45: =IFERROR(VLOOKUP(C45,_Listas!$C$2:$H$80,3,0)*D45/100,0) -> 0.03 | G45: =IFERROR(VLOOKUP(C45,_Listas!$C$2:$H$80,4,0)*D45/100,0) -> 26.34 | H45: =IFERROR(VLOOKUP(C45,_Listas!$C$2:$H$80,5,0)*D45/100,0) -> 0.09 | I45: 1 tapioca peq.
C46: Ovo de galinha cozido | D46: 100 | E46: =IFERROR(VLOOKUP(C46,_Listas!$C$2:$H$80,2,0)*D46/100,0) -> 146 | F46: =IFERROR(VLOOKUP(C46,_Listas!$C$2:$H$80,3,0)*D46/100,0) -> 13.3 | G46: =IFERROR(VLOOKUP(C46,_Listas!$C$2:$H$80,4,0)*D46/100,0) -> 0.6 | H46: =IFERROR(VLOOKUP(C46,_Listas!$C$2:$H$80,5,0)*D46/100,0) -> 10 | I46: 2 unidades
C47: Queijo mussarela | D47: 20 | E47: =IFERROR(VLOOKUP(C47,_Listas!$C$2:$H$80,2,0)*D47/100,0) -> 57.8 | F47: =IFERROR(VLOOKUP(C47,_Listas!$C$2:$H$80,3,0)*D47/100,0) -> 3.6 | G47: =IFERROR(VLOOKUP(C47,_Listas!$C$2:$H$80,4,0)*D47/100,0) -> 0.52 | H47: =IFERROR(VLOOKUP(C47,_Listas!$C$2:$H$80,5,0)*D47/100,0) -> 4.58 | I47: 1 fatia
C48: Filé de frango grelhado | D48: 80 | E48: =IFERROR(VLOOKUP(C48,_Listas!$C$2:$H$80,2,0)*D48/100,0) -> 130.4 | F48: =IFERROR(VLOOKUP(C48,_Listas!$C$2:$H$80,3,0)*D48/100,0) -> 25.2 | G48: =IFERROR(VLOOKUP(C48,_Listas!$C$2:$H$80,4,0)*D48/100,0) -> 0 | H48: =IFERROR(VLOOKUP(C48,_Listas!$C$2:$H$80,5,0)*D48/100,0) -> 2.96 | I48: 1 filé pequeno
...

Sheet SAB
B2: 🍽️ PLANO ALIMENTAR · Sábado 🟢 · (=Ter e Qui)
B3: ▼ Clique na seta ▼ em cada alimento para trocar · Edite a porção (g) para recalcular as calorias automaticamente
B4: Meta Kcal/dia: | C4: 2000 | D4: Peso (kg): | E4: 70 | F4: Objetivo: | G4: Emagrecimento
B6: Refeição / Horário | C6: Alimento ▼ | D6: Porção (g) | E6: Kcal | F6: Prot. (g) | G6: Carb. (g) | H6: Gord. (g) | I6: Medida caseira
B8: ☕ Café da Manhã 08:00h
B9: ☕ Café da Manhã | C9: Café sem açúcar | D9: 200 | E9: =IFERROR(VLOOKUP(C9,_Listas!$C$2:$H$80,2,0)*D9/100,0) -> 4 | F9: =IFERROR(VLOOKUP(C9,_Listas!$C$2:$H$80,3,0)*D9/100,0) -> 0.6 | G9: =IFERROR(VLOOKUP(C9,_Listas!$C$2:$H$80,4,0)*D9/100,0) -> 0 | H9: =IFERROR(VLOOKUP(C9,_Listas!$C$2:$H$80,5,0)*D9/100,0) -> 0 | I9: 200 ml
C10: Pão francês | D10: 60 | E10: =IFERROR(VLOOKUP(C10,_Listas!$C$2:$H$80,2,0)*D10/100,0) -> 180 | F10: =IFERROR(VLOOKUP(C10,_Listas!$C$2:$H$80,3,0)*D10/100,0) -> 4.8 | G10: =IFERROR(VLOOKUP(C10,_Listas!$C$2:$H$80,4,0)*D10/100,0) -> 35.16 | H10: =IFERROR(VLOOKUP(C10,_Listas!$C$2:$H$80,5,0)*D10/100,0) -> 1.86 | I10: 1 unidade
C11: Requeijão | D11: 15 | E11: =IFERROR(VLOOKUP(C11,_Listas!$C$2:$H$80,2,0)*D11/100,0) -> 36 | F11: =IFERROR(VLOOKUP(C11,_Listas!$C$2:$H$80,3,0)*D11/100,0) -> 1.05 | G11: =IFERROR(VLOOKUP(C11,_Listas!$C$2:$H$80,4,0)*D11/100,0) -> 0.525 | H11: =IFERROR(VLOOKUP(C11,_Listas!$C$2:$H$80,5,0)*D11/100,0) -> 3.3 | I11: 1 col. sopa
C12: Queijo mussarela | D12: 20 | E12: =IFERROR(VLOOKUP(C12,_Listas!$C$2:$H$80,2,0)*D12/100,0) -> 57.8 | F12: =IFERROR(VLOOKUP(C12,_Listas!$C$2:$H$80,3,0)*D12/100,0) -> 3.6 | G12: =IFERROR(VLOOKUP(C12,_Listas!$C$2:$H$80,4,0)*D12/100,0) -> 0.52 | H12: =IFERROR(VLOOKUP(C12,_Listas!$C$2:$H$80,5,0)*D12/100,0) -> 4.58 | I12: 1 fatia
C13: Peito de peru fatiado | D13: 15 | E13: =IFERROR(VLOOKUP(C13,_Listas!$C$2:$H$80,2,0)*D13/100,0) -> 16.35 | F13: =IFERROR(VLOOKUP(C13,_Listas!$C$2:$H$80,3,0)*D13/100,0) -> 2.61 | G13: =IFERROR(VLOOKUP(C13,_Listas!$C$2:$H$80,4,0)*D13/100,0) -> 0.285 | H13: =IFERROR(VLOOKUP(C13,_Listas!$C$2:$H$80,5,0)*D13/100,0) -> 0.54 | I13: 1 fatia
C14: Maçã com casca | D14: 120 | E14: =IFERROR(VLOOKUP(C14,_Listas!$C$2:$H$80,2,0)*D14/100,0) -> 67.2 | F14: =IFERROR(VLOOKUP(C14,_Listas!$C$2:$H$80,3,0)*D14/100,0) -> 0.36 | G14: =IFERROR(VLOOKUP(C14,_Listas!$C$2:$H$80,4,0)*D14/100,0) -> 17.88 | H14: =IFERROR(VLOOKUP(C14,_Listas!$C$2:$H$80,5,0)*D14/100,0) -> 0.12 | I14: 1 unid. média
C15: Creatina monohidratada | D15: 6 | E15: =IFERROR(VLOOKUP(C15,_Listas!$C$2:$H$80,2,0)*D15/100,0) -> 0 | F15: =IFERROR(VLOOKUP(C15,_Listas!$C$2:$H$80,3,0)*D15/100,0) -> 0 | G15: =IFERROR(VLOOKUP(C15,_Listas!$C$2:$H$80,4,0)*D15/100,0) -> 0 | H15: =IFERROR(VLOOKUP(C15,_Listas!$C$2:$H$80,5,0)*D15/100,0) -> 0 | I15: 2 doses
B16: Subtotal ☕ Café da Manhã | D16: =SUM(D9:D15) -> 436 | E16: =SUM(E9:E15) -> 361.35 | F16: =SUM(F9:F15) -> 13.02 | G16: =SUM(G9:G15) -> 54.37 | H16: =SUM(H9:H15) -> 10.4
B18: 🍌 Lanche 10:00h
B19: 🍌 Lanche | C19: Yopro 15g High Protein | D19: 300 | E19: =IFERROR(VLOOKUP(C19,_Listas!$C$2:$H$80,2,0)*D19/100,0) -> 201 | F19: =IFERROR(VLOOKUP(C19,_Listas!$C$2:$H$80,3,0)*D19/100,0) -> 20.1 | G19: =IFERROR(VLOOKUP(C19,_Listas!$C$2:$H$80,4,0)*D19/100,0) -> 30 | H19: =IFERROR(VLOOKUP(C19,_Listas!$C$2:$H$80,5,0)*D19/100,0) -> 0 | I19: 1 unidade
B20: Subtotal 🍌 Lanche | D20: =SUM(D19:D19) -> 300 | E20: =SUM(E19:E19) -> 201 | F20: =SUM(F19:F19) -> 20.1 | G20: =SUM(G19:G19) -> 30 | H20: =SUM(H19:H19) -> 0
B22: 🥗 Almoço 13:00h
B23: 🥗 Almoço | C23: Arroz branco cozido | D23: 140 | E23: =IFERROR(VLOOKUP(C23,_Listas!$C$2:$H$80,2,0)*D23/100,0) -> 179.2 | F23: =IFERROR(VLOOKUP(C23,_Listas!$C$2:$H$80,3,0)*D23/100,0) -> 3.5 | G23: =IFERROR(VLOOKUP(C23,_Listas!$C$2:$H$80,4,0)*D23/100,0) -> 39.34 | H23: =IFERROR(VLOOKUP(C23,_Listas!$C$2:$H$80,5,0)*D23/100,0) -> 0.28 | I23: 4 col. sopa
C24: Patê de ricota | D24: 20 | E24: =IFERROR(VLOOKUP(C24,_Listas!$C$2:$H$80,2,0)*D24/100,0) -> 34 | F24: =IFERROR(VLOOKUP(C24,_Listas!$C$2:$H$80,3,0)*D24/100,0) -> 1.6 | G24: =IFERROR(VLOOKUP(C24,_Listas!$C$2:$H$80,4,0)*D24/100,0) -> 1 | H24: =IFERROR(VLOOKUP(C24,_Listas!$C$2:$H$80,5,0)*D24/100,0) -> 2.6 | I24: 1 col. sopa
C25: Requeijão | D25: 40 | E25: =IFERROR(VLOOKUP(C25,_Listas!$C$2:$H$80,2,0)*D25/100,0) -> 96 | F25: =IFERROR(VLOOKUP(C25,_Listas!$C$2:$H$80,3,0)*D25/100,0) -> 2.8 | G25: =IFERROR(VLOOKUP(C25,_Listas!$C$2:$H$80,4,0)*D25/100,0) -> 1.4 | H25: =IFERROR(VLOOKUP(C25,_Listas!$C$2:$H$80,5,0)*D25/100,0) -> 8.8 | I25: 2 col. sopa
C26: Filé de frango grelhado | D26: 170 | E26: =IFERROR(VLOOKUP(C26,_Listas!$C$2:$H$80,2,0)*D26/100,0) -> 277.1 | F26: =IFERROR(VLOOKUP(C26,_Listas!$C$2:$H$80,3,0)*D26/100,0) -> 53.55 | G26: =IFERROR(VLOOKUP(C26,_Listas!$C$2:$H$80,4,0)*D26/100,0) -> 0 | H26: =IFERROR(VLOOKUP(C26,_Listas!$C$2:$H$80,5,0)*D26/100,0) -> 6.29 | I26: 1 filé grande
C27: Laranja pera | D27: 150 | E27: =IFERROR(VLOOKUP(C27,_Listas!$C$2:$H$80,2,0)*D27/100,0) -> 69 | F27: =IFERROR(VLOOKUP(C27,_Listas!$C$2:$H$80,3,0)*D27/100,0) -> 1.35 | G27: =IFERROR(VLOOKUP(C27,_Listas!$C$2:$H$80,4,0)*D27/100,0) -> 17.25 | H27: =IFERROR(VLOOKUP(C27,_Listas!$C$2:$H$80,5,0)*D27/100,0) -> 0.15 | I27: 1 unidade grande
B28: Subtotal 🥗 Almoço | D28: =SUM(D23:D27) -> 520 | E28: =SUM(E23:E27) -> 655.3 | F28: =SUM(F23:F27) -> 62.8 | G28: =SUM(G23:G27) -> 58.99 | H28: =SUM(H23:H27) -> 18.12
B30: 🔄 Opção Almoço (alternativa)
B31: 🔄 Opção Almoço | C31: Purê de batata caseiro | D31: 150 | E31: =IFERROR(VLOOKUP(C31,_Listas!$C$2:$H$80,2,0)*D31/100,0) -> 153 | F31: =IFERROR(VLOOKUP(C31,_Listas!$C$2:$H$80,3,0)*D31/100,0) -> 3.75 | G31: =IFERROR(VLOOKUP(C31,_Listas!$C$2:$H$80,4,0)*D31/100,0) -> 25.5 | H31: =IFERROR(VLOOKUP(C31,_Listas!$C$2:$H$80,5,0)*D31/100,0) -> 4.5 | I31: 1 porção
C32: Moranga cozida | D32: 100 | E32: =IFERROR(VLOOKUP(C32,_Listas!$C$2:$H$80,2,0)*D32/100,0) -> 26 | F32: =IFERROR(VLOOKUP(C32,_Listas!$C$2:$H$80,3,0)*D32/100,0) -> 0.7 | G32: =IFERROR(VLOOKUP(C32,_Listas!$C$2:$H$80,4,0)*D32/100,0) -> 6 | H32: =IFERROR(VLOOKUP(C32,_Listas!$C$2:$H$80,5,0)*D32/100,0) -> 0.1 | I32: 1 porção
C33: Peixe grelhado | D33: 200 | E33: =IFERROR(VLOOKUP(C33,_Listas!$C$2:$H$80,2,0)*D33/100,0) -> 256 | F33: =IFERROR(VLOOKUP(C33,_Listas!$C$2:$H$80,3,0)*D33/100,0) -> 50 | G33: =IFERROR(VLOOKUP(C33,_Listas!$C$2:$H$80,4,0)*D33/100,0) -> 0 | H33: =IFERROR(VLOOKUP(C33,_Listas!$C$2:$H$80,5,0)*D33/100,0) -> 5.6 | I33: 1 filé
C34: Legumes cozidos variados | D34: 120 | E34: =IFERROR(VLOOKUP(C34,_Listas!$C$2:$H$80,2,0)*D34/100,0) -> 42 | F34: =IFERROR(VLOOKUP(C34,_Listas!$C$2:$H$80,3,0)*D34/100,0) -> 2.4 | G34: =IFERROR(VLOOKUP(C34,_Listas!$C$2:$H$80,4,0)*D34/100,0) -> 7.8 | H34: =IFERROR(VLOOKUP(C34,_Listas!$C$2:$H$80,5,0)*D34/100,0) -> 0.36 | I34: 2 porções
C35: Bombom Ouro Branco | D35: 16 | E35: =IFERROR(VLOOKUP(C35,_Listas!$C$2:$H$80,2,0)*D35/100,0) -> 83.2 | F35: =IFERROR(VLOOKUP(C35,_Listas!$C$2:$H$80,3,0)*D35/100,0) -> 0.8 | G35: =IFERROR(VLOOKUP(C35,_Listas!$C$2:$H$80,4,0)*D35/100,0) -> 9.6 | H35: =IFERROR(VLOOKUP(C35,_Listas!$C$2:$H$80,5,0)*D35/100,0) -> 4.48 | I35: 1 unidade
B37: ☕ Café da Tarde 18:00h
B38: ☕ Café da Tarde | C38: Leite de vaca integral | D38: 200 | E38: =IFERROR(VLOOKUP(C38,_Listas!$C$2:$H$80,2,0)*D38/100,0) -> 122 | F38: =IFERROR(VLOOKUP(C38,_Listas!$C$2:$H$80,3,0)*D38/100,0) -> 6.4 | G38: =IFERROR(VLOOKUP(C38,_Listas!$C$2:$H$80,4,0)*D38/100,0) -> 9.4 | H38: =IFERROR(VLOOKUP(C38,_Listas!$C$2:$H$80,5,0)*D38/100,0) -> 6.4 | I38: 1 copo
C39: Banana | D39: 60 | E39: =IFERROR(VLOOKUP(C39,_Listas!$C$2:$H$80,2,0)*D39/100,0) -> 55.2 | F39: =IFERROR(VLOOKUP(C39,_Listas!$C$2:$H$80,3,0)*D39/100,0) -> 0.78 | G39: =IFERROR(VLOOKUP(C39,_Listas!$C$2:$H$80,4,0)*D39/100,0) -> 14.28 | H39: =IFERROR(VLOOKUP(C39,_Listas!$C$2:$H$80,5,0)*D39/100,0) -> 0.06 | I39: ½ unidade
C40: Whey protein | D40: 60 | E40: =IFERROR(VLOOKUP(C40,_Listas!$C$2:$H$80,2,0)*D40/100,0) -> 224.4 | F40: =IFERROR(VLOOKUP(C40,_Listas!$C$2:$H$80,3,0)*D40/100,0) -> 48 | G40: =IFERROR(VLOOKUP(C40,_Listas!$C$2:$H$80,4,0)*D40/100,0) -> 4.8 | H40: =IFERROR(VLOOKUP(C40,_Listas!$C$2:$H$80,5,0)*D40/100,0) -> 2.4 | I40: 2 scoops
B41: Subtotal ☕ Café da Tarde | D41: =SUM(D38:D40) -> 320 | E41: =SUM(E38:E40) -> 401.6 | F41: =SUM(F38:F40) -> 55.18 | G41: =SUM(G38:G40) -> 28.48 | H41: =SUM(H38:H40) -> 8.86
B43: 🌙 Jantar 20:30h
B44: 🌙 Jantar | C44: Coca-Cola Light | D44: 350 | E44: =IFERROR(VLOOKUP(C44,_Listas!$C$2:$H$80,2,0)*D44/100,0) -> 3.5 | F44: =IFERROR(VLOOKUP(C44,_Listas!$C$2:$H$80,3,0)*D44/100,0) -> 0 | G44: =IFERROR(VLOOKUP(C44,_Listas!$C$2:$H$80,4,0)*D44/100,0) -> 1.05 | H44: =IFERROR(VLOOKUP(C44,_Listas!$C$2:$H$80,5,0)*D44/100,0) -> 0 | I44: 1 lata
C45: Pão de hambúrguer | D45: 70 | E45: =IFERROR(VLOOKUP(C45,_Listas!$C$2:$H$80,2,0)*D45/100,0) -> 196 | F45: =IFERROR(VLOOKUP(C45,_Listas!$C$2:$H$80,3,0)*D45/100,0) -> 5.6 | G45: =IFERROR(VLOOKUP(C45,_Listas!$C$2:$H$80,4,0)*D45/100,0) -> 35 | H45: =IFERROR(VLOOKUP(C45,_Listas!$C$2:$H$80,5,0)*D45/100,0) -> 3.5 | I45: 1 unidade
C46: Queijo mussarela | D46: 25 | E46: =IFERROR(VLOOKUP(C46,_Listas!$C$2:$H$80,2,0)*D46/100,0) -> 72.25 | F46: =IFERROR(VLOOKUP(C46,_Listas!$C$2:$H$80,3,0)*D46/100,0) -> 4.5 | G46: =IFERROR(VLOOKUP(C46,_Listas!$C$2:$H$80,4,0)*D46/100,0) -> 0.65 | H46: =IFERROR(VLOOKUP(C46,_Listas!$C$2:$H$80,5,0)*D46/100,0) -> 5.725 | I46: 1 fatia
